Workbook
Name buyuksehir_ve_il_belediyeleri: Excel3!#REF!

Sheet laroux

Sheet Excel6
A1: İLÇE/İL | B1: BANKAADI | C1: ŞUBEADI | D1: BANKAKODU | E1: ŞUBEKODU | F1: IBAN | G1: IBANKONTROL | H1: YSVTUTARI | I1: BELEDİYEBAŞK. | J1: İLÇE1 | K1: İL1 | L1: TXTİÇİN | M1: POSTA İÇİN
A2: AKÇATEKİR / ADANA | B2: HALKBANKASI | C2: AKÇATEKİR | D2: 12 | E2: 90001 | F2: TR200001200916300007000004 | G2: =LEN(F2) -> 26 | H2: =IF(ISERROR(VLOOKUP(A2,Excel4!D:J,7,0)),0,VLOOKUP(A2,Excel4!D:J,7,0)) -> 0 | I2: BELEDİYE BAŞKANLIĞI | J2: AKÇATEKİR | K2: ADANA | L2: =IF(J2="MERKEZ",K2&" "&I2,IF(J2="BÜYÜKŞEHİR",K2&" "&J2&" "&I2,J2&" "&I2&" "&K2)) -> AKÇATEKİR BELEDİYE BAŞKANLIĞI ADANA | M2: =IF(J2="MERKEZ",K2,IF(J2="BÜYÜKŞEHİR",K2&" BÜYÜKŞEHİR",J2)) -> AKÇATEKİR
A3: ALADAĞ / ADANA | B3: ZİRAAT BANKASI | C3: ALADAĞ | D3: 10 | E3: 90001 | F3: TR510001001062301054525001 | G3: =LEN(F3) -> 26 | H3: =IF(ISERROR(VLOOKUP(A3,Excel4!D:J,7,0)),0,VLOOKUP(A3,Excel4!D:J,7,0)) -> 0 | I3: BELEDİYE BAŞKANLIĞI | J3: ALADAĞ | K3: ADANA | L3: =IF(J3="MERKEZ",K3&" "&I3,IF(J3="BÜYÜKŞEHİR",K3&" "&J3&" "&I3,J3&" "&I3&" "&K3)) -> ALADAĞ BELEDİYE BAŞKANLIĞI ADANA | M3: =IF(J3="MERKEZ",K3,IF(J3="BÜYÜKŞEHİR",K3&" BÜYÜKŞEHİR",J3)) -> ALADAĞ
A4: ADANA BÜYÜKŞEHİR / ADANA | B4: VAKIFBANK | C4: ADANA | D4: 15 | E4: 90001 | F4: TR110001500158007264554493 | G4: =LEN(F4) -> 26 | H4: =IF(ISERROR(VLOOKUP(A4,Excel4!D:J,7,0)),0,VLOOKUP(A4,Excel4!D:J,7,0)) -> 30476.1 | I4: BELEDİYE BAŞKANLIĞI | J4: BÜYÜKŞEHİR | K4: ADANA | L4: =IF(J4="MERKEZ",K4&" "&I4,IF(J4="BÜYÜKŞEHİR",K4&" "&J4&" "&I4,J4&" "&I4&" "&K4)) -> ADANA BÜYÜKŞEHİR BELEDİYE BAŞKANLIĞI | M4: =IF(J4="MERKEZ",K4,IF(J4="BÜYÜKŞEHİR",K4&" BÜYÜKŞEHİR",J4)) -> ADANA BÜYÜKŞEHİR | N4: =_xlfn.XLOOKUP(M4,[1]Sheet1!$A:$A,[1]Sheet1!$G:$G) -> 0
A5: CEYHAN / ADANA | B5: ZİRAAT BANKASI | C5: CEYHAN | D5: 10 | E5: 90001 | F5: TR380001000015480566185001 | G5: =LEN(F5) -> 26 | H5: =IF(ISERROR(VLOOKUP(A5,Excel4!D:J,7,0)),0,VLOOKUP(A5,Excel4!D:J,7,0)) -> 0 | I5: BELEDİYE BAŞKANLIĞI | J5: CEYHAN | K5: ADANA | L5: =IF(J5="MERKEZ",K5&" "&I5,IF(J5="BÜYÜKŞEHİR",K5&" "&J5&" "&I5,J5&" "&I5&" "&K5)) -> CEYHAN BELEDİYE BAŞKANLIĞI ADANA | M5: =IF(J5="MERKEZ",K5,IF(J5="BÜYÜKŞEHİR",K5&" BÜYÜKŞEHİR",J5)) -> CEYHAN
A6: ÇUKUROVA / ADANA | B6: ZİRAAT BANKASI | C6: ÇUKUROVA | D6: 10 | E6: 90001 | F6: TR850001001922523052755001 | G6: =LEN(F6) -> 26 | H6: =IF(ISERROR(VLOOKUP(A6,Excel4!D:J,7,0)),0,VLOOKUP(A6,Excel4!D:J,7,0)) -> 0 | I6: BELEDİYE BAŞKANLIĞI | J6: ÇUKUROVA | K6: ADANA | L6: =IF(J6="MERKEZ",K6&" "&I6,IF(J6="BÜYÜKŞEHİR",K6&" "&J6&" "&I6,J6&" "&I6&" "&K6)) -> ÇUKUROVA BELEDİYE BAŞKANLIĞI ADANA | M6: =IF(J6="MERKEZ",K6,IF(J6="BÜYÜKŞEHİR",K6&" BÜYÜKŞEHİR",J6)) -> ÇUKUROVA
A7: İMAMOĞLU / ADANA | B7: İŞ BANKASI | C7: İMAMOĞLU | D7: 64 | E7: 90001 | F7: TR190006400000160250241962 | G7: =LEN(F7) -> 26 | H7: =IF(ISERROR(VLOOKUP(A7,Excel4!D:J,7,0)),0,VLOOKUP(A7,Excel4!D:J,7,0)) -> 0 | I7: BELEDİYE BAŞKANLIĞI | J7: İMAMOĞLU | K7: ADANA | L7: =IF(J7="MERKEZ",K7&" "&I7,IF(J7="BÜYÜKŞEHİR",K7&" "&J7&" "&I7,J7&" "&I7&" "&K7)) -> İMAMOĞLU BELEDİYE BAŞKANLIĞI ADANA | M7: =IF(J7="MERKEZ",K7,IF(J7="BÜYÜKŞEHİR",K7&" BÜYÜKŞEHİR",J7)) -> İMAMOĞLU
A8: KARAİSALI / ADANA | B8: ZİRAAT BANKASI | C8: KARAİSALI | D8: 10 | E8: 90001 | F8: TR110001000017253406625001 | G8: =LEN(F8) -> 26 | H8: =IF(ISERROR(VLOOKUP(A8,Excel4!D:J,7,0)),0,VLOOKUP(A8,Excel4!D:J,7,0)) -> 0 | I8: BELEDİYE BAŞKANLIĞI | J8: KARAİSALI | K8: ADANA | L8: =IF(J8="MERKEZ",K8&" "&I8,IF(J8="BÜYÜKŞEHİR",K8&" "&J8&" "&I8,J8&" "&I8&" "&K8)) -> KARAİSALI BELEDİYE BAŞKANLIĞI ADANA | M8: =IF(J8="MERKEZ",K8,IF(J8="BÜYÜKŞEHİR",K8&" BÜYÜKŞEHİR",J8)) -> KARAİSALI
A9: KARATAŞ / ADANA | B9: ZİRAAT BANKASI | C9: KARATAŞ | D9: 10 | E9: 90001 | F9: TR330001000931304420615011 | G9: =LEN(F9) -> 26 | H9: =IF(ISERROR(VLOOKUP(A9,Excel4!D:J,7,0)),0,VLOOKUP(A9,Excel4!D:J,7,0)) -> 0 | I9: BELEDİYE BAŞKANLIĞI | J9: KARATAŞ | K9: ADANA | L9: =IF(J9="MERKEZ",K9&" "&I9,IF(J9="BÜYÜKŞEHİR",K9&" "&J9&" "&I9,J9&" "&I9&" "&K9)) -> KARATAŞ BELEDİYE BAŞKANLIĞI ADANA | M9: =IF(J9="MERKEZ",K9,IF(J9="BÜYÜKŞEHİR",K9&" BÜYÜKŞEHİR",J9)) -> KARATAŞ
A10: KOZAN / ADANA | B10: HALKBANKASI | C10: KOZAN | D10: 12 | E10: 90001 | F10: TR960001200916100007000004 | G10: =LEN(F10) -> 26 | H10: =IF(ISERROR(VLOOKUP(A10,Excel4!D:J,7,0)),0,VLOOKUP(A10,Excel4!D:J,7,0)) -> 0 | I10: BELEDİYE BAŞKANLIĞI | J10: KOZAN | K10: ADANA | L10: =IF(J10="MERKEZ",K10&" "&I10,IF(J10="BÜYÜKŞEHİR",K10&" "&J10&" "&I10,J10&" "&I10&" "&K10)) -> KOZAN BELEDİYE BAŞKANLIĞI ADANA | M10: =IF(J10="MERKEZ",K10,IF(J10="BÜYÜKŞEHİR",K10&" BÜYÜKŞEHİR",J10)) -> KOZAN
A11: POZANTI / ADANA | B11: ZİRAAT BANKASI | C11: POZANTI | D11: 10 | E11: 90001 | F11: TR930001000493333283045001 | G11: =LEN(F11) -> 26 | H11: =IF(ISERROR(VLOOKUP(A11,Excel4!D:J,7,0)),0,VLOOKUP(A11,Excel4!D:J,7,0)) -> 0 | I11: BELEDİYE BAŞKANLIĞI | J11: POZANTI | K11: ADANA | L11: =IF(J11="MERKEZ",K11&" "&I11,IF(J11="BÜYÜKŞEHİR",K11&" "&J11&" "&I11,J11&" "&I11&" "&K11)) -> POZANTI BELEDİYE BAŞKANLIĞI ADANA | M11: =IF(J11="MERKEZ",K11,IF(J11="BÜYÜKŞEHİR",K11&" BÜYÜKŞEHİR",J11)) -> POZANTI
A12: SEYHAN / ADANA | B12: VAKIFBANK | C12: SEYHAN | D12: 15 | E12: 90001 | F12: TR790001500158007281705682 | G12: =LEN(F12) -> 26 | H12: =IF(ISERROR(VLOOKUP(A12,Excel4!D:J,7,0)),0,VLOOKUP(A12,Excel4!D:J,7,0)) -> 0 | I12: BELEDİYE BAŞKANLIĞI | J12: SEYHAN | K12: ADANA | L12: =IF(J12="MERKEZ",K12&" "&I12,IF(J12="BÜYÜKŞEHİR",K12&" "&J12&" "&I12,J12&" "&I12&" "&K12)) -> SEYHAN BELEDİYE BAŞKANLIĞI ADANA | M12: =IF(J12="MERKEZ",K12,IF(J12="BÜYÜKŞEHİR",K12&" BÜYÜKŞEHİR",J12)) -> SEYHAN
A13: TUFANBEYLİ / ADANA | B13: ZİRAAT BANKASI | C13: TUFANBEYLİ | D13: 10 | E13: 90001 | F13: TR510001000573308580215008 | G13: =LEN(F13) -> 26 | H13: =IF(ISERROR(VLOOKUP(A13,Excel4!D:J,7,0)),0,VLOOKUP(A13,Excel4!D:J,7,0)) -> 0 | I13: BELEDİYE BAŞKANLIĞI | J13: TUFANBEYLİ | K13: ADANA | L13: =IF(J13="MERKEZ",K13&" "&I13,IF(J13="BÜYÜKŞEHİR",K13&" "&J13&" "&I13,J13&" "&I13&" "&K13)) -> TUFANBEYLİ BELEDİYE BAŞKANLIĞI ADANA | M13: =IF(J13="MERKEZ",K13,IF(J13="BÜYÜKŞEHİR",K13&" BÜYÜKŞEHİR",J13)) -> TUFANBEYLİ
A14: YUMURTALIK / ADANA | B14: ZİRAAT BANKASI | C14: YUMURTALIK | D14: 10 | E14: 90001 | F14: TR730001000612429091055008 | G14: =LEN(F14) -> 26 | H14: =IF(ISERROR(VLOOKUP(A14,Excel4!D:J,7,0)),0,VLOOKUP(A14,Excel4!D:J,7,0)) -> 0 | I14: BELEDİYE BAŞKANLIĞI | J14: YUMURTALIK | K14: ADANA | L14: =IF(J14="MERKEZ",K14&" "&I14,IF(J14="BÜYÜKŞEHİR",K14&" "&J14&" "&I14,J14&" "&I14&" "&K14)) -> YUMURTALIK BELEDİYE BAŞKANLIĞI ADANA | M14: =IF(J14="MERKEZ",K14,IF(J14="BÜYÜKŞEHİR",K14&" BÜYÜKŞEHİR",J14)) -> YUMURTALIK
A15: BESNİ / ADIYAMAN | B15: HALKBANKASI | C15: BESNİ | D15: 12 | E15: 90001 | F15: TR470001200918200007000005 | G15: =LEN(F15) -> 26 | H15: =IF(ISERROR(VLOOKUP(A15,Excel4!D:J,7,0)),0,VLOOKUP(A15,Excel4!D:J,7,0)) -> 71.07 | I15: BELEDİYE BAŞKANLIĞI | J15: BESNİ | K15: ADIYAMAN | L15: =IF(J15="MERKEZ",K15&" "&I15,IF(J15="BÜYÜKŞEHİR",K15&" "&J15&" "&I15,J15&" "&I15&" "&K15)) -> BESNİ BELEDİYE BAŞKANLIĞI ADIYAMAN | M15: =IF(J15="MERKEZ",K15,IF(J15="BÜYÜKŞEHİR",K15&" BÜYÜKŞEHİR",J15)) -> BESNİ | N15: =_xlfn.XLOOKUP(M15,[1]Sheet1!$A:$A,[1]Sheet1!$G:$G) -> 0
A16: BÖLÜKYAYLA / ADIYAMAN | B16: HALKBANKASI | C16: KAHTA | D16: 12 | E16: 90001 | F16: TR180001200125400007000009 | G16: =LEN(F16) -> 26 | H16: =IF(ISERROR(VLOOKUP(A16,Excel4!D:J,7,0)),0,VLOOKUP(A16,Excel4!D:J,7,0)) -> 0 | I16: BELEDİYE BAŞKANLIĞI | J16: BÖLÜKYAYLA | K16: ADIYAMAN | L16: =IF(J16="MERKEZ",K16&" "&I16,IF(J16="BÜYÜKŞEHİR",K16&" "&J16&" "&I16,J16&" "&I16&" "&K16)) -> BÖLÜKYAYLA BELEDİYE BAŞKANLIĞI ADIYAMAN | M16: =IF(J16="MERKEZ",K16,IF(J16="BÜYÜKŞEHİR",K16&" BÜYÜKŞEHİR",J16)) -> BÖLÜKYAYLA
A17: ÇAKIRHÜYÜK / ADIYAMAN | B17: HALKBANKASI | C17: BESNİ | D17: 12 | E17: 90001 | F17: TR840001200918200004000002 | G17: =LEN(F17) -> 26 | H17: =IF(ISERROR(VLOOKUP(A17,Excel4!D:J,7,0)),0,VLOOKUP(A17,Excel4!D:J,7,0)) -> 0 | I17: BELEDİYE BAŞKANLIĞI | J17: ÇAKIRHÜYÜK | K17: ADIYAMAN | L17: =IF(J17="MERKEZ",K17&" "&I17,IF(J17="BÜYÜKŞEHİR",K17&" "&J17&" "&I17,J17&" "&I17&" "&K17)) -> ÇAKIRHÜYÜK BELEDİYE BAŞKANLIĞI ADIYAMAN | M17: =IF(J17="MERKEZ",K17,IF(J17="BÜYÜKŞEHİR",K17&" BÜYÜKŞEHİR",J17)) -> ÇAKIRHÜYÜK
A18: ÇELİKHAN / ADIYAMAN | B18: ZİRAAT BANKASI | C18: ÇELİKHAN | D18: 10 | E18: 90001 | F18: TR880001000695286188985001 | G18: 26 | H18: =IF(ISERROR(VLOOKUP(A18,Excel4!D:J,7,0)),0,VLOOKUP(A18,Excel4!D:J,7,0)) -> 42.54 | I18: BELEDİYE BAŞKANLIĞI | J18: ÇELİKHAN | K18: ADIYAMAN | L18: =IF(J18="MERKEZ",K18&" "&I18,IF(J18="BÜYÜKŞEHİR",K18&" "&J18&" "&I18,J18&" "&I18&" "&K18)) -> ÇELİKHAN BELEDİYE BAŞKANLIĞI ADIYAMAN | M18: =IF(J18="MERKEZ",K18,IF(J18="BÜYÜKŞEHİR",K18&" BÜYÜKŞEHİR",J18)) -> ÇELİKHAN | N18: =_xlfn.XLOOKUP(M18,[1]Sheet1!$A:$A,[1]Sheet1!$G:$G) -> 0
A19: GERGER / ADIYAMAN | B19: ZİRAAT BANKASI | C19: GERGER | D19: 10 | E19: 90001 | F19: TR880001000690254849425001 | G19: 26 | H19: =IF(ISERROR(VLOOKUP(A19,Excel4!D:J,7,0)),0,VLOOKUP(A19,Excel4!D:J,7,0)) -> 0 | I19: BELEDİYE BAŞKANLIĞI | J19: GERGER | K19: ADIYAMAN | L19: =IF(J19="MERKEZ",K19&" "&I19,IF(J19="BÜYÜKŞEHİR",K19&" "&J19&" "&I19,J19&" "&I19&" "&K19)) -> GERGER BELEDİYE BAŞKANLIĞI ADIYAMAN | M19: =IF(J19="MERKEZ",K19,IF(J19="BÜYÜKŞEHİR",K19&" BÜYÜKŞEHİR",J19)) -> GERGER
A20: GÖLBAŞI / ADIYAMAN | B20: ZİRAAT BANKASI | C20: GÖLBAŞI | D20: 10 | E20: 90001 | F20: TR760001000643294316505006 | G20: =LEN(F20) -> 26 | H20: =IF(ISERROR(VLOOKUP(A20,Excel4!D:J,7,0)),0,VLOOKUP(A20,Excel4!D:J,7,0)) -> 22.29 | I20: BELEDİYE BAŞKANLIĞI | J20: GÖLBAŞI | K20: ADIYAMAN | L20: =IF(J20="MERKEZ",K20&" "&I20,IF(J20="BÜYÜKŞEHİR",K20&" "&J20&" "&I20,J20&" "&I20&" "&K20)) -> GÖLBAŞI BELEDİYE BAŞKANLIĞI ADIYAMAN | M20: =IF(J20="MERKEZ",K20,IF(J20="BÜYÜKŞEHİR",K20&" BÜYÜKŞEHİR",J20)) -> GÖLBAŞI | N20: =_xlfn.XLOOKUP(M20,[1]Sheet1!$A:$A,[1]Sheet1!$G:$G) -> 0
A21: KAHTA / ADIYAMAN | B21: HALKBANKASI | C21: KAHTA | D21: 12 | E21: 90001 | F21: TR340001200125400007000012 | G21: =LEN(F21) -> 26 | H21: =IF(ISERROR(VLOOKUP(A21,Excel4!D:J,7,0)),0,VLOOKUP(A21,Excel4!D:J,7,0)) -> 505.69 | I21: BELEDİYE BAŞKANLIĞI | J21: KAHTA | K21: ADIYAMAN | L21: =IF(J21="MERKEZ",K21&" "&I21,IF(J21="BÜYÜKŞEHİR",K21&" "&J21&" "&I21,J21&" "&I21&" "&K21)) -> KAHTA BELEDİYE BAŞKANLIĞI ADIYAMAN | M21: =IF(J21="MERKEZ",K21,IF(J21="BÜYÜKŞEHİR",K21&" BÜYÜKŞEHİR",J21)) -> KAHTA | N21: =_xlfn.XLOOKUP(M21,[1]Sheet1!$A:$A,[1]Sheet1!$G:$G) -> 0
A22: KARICIK / ADIYAMAN | B22: HALKBANKASI | C22: MERKEZ | D22: 12 | E22: 9181 | F22: TR690001200918100007000002 | G22: =LEN(F22) -> 26 | H22: =IF(ISERROR(VLOOKUP(A22,Excel4!D:J,7,0)),0,VLOOKUP(A22,Excel4!D:J,7,0)) -> 0 | I22: BELEDİYE BAŞKANLIĞI | J22: KARICIK | K22: ADIYAMAN | L22: =IF(J22="MERKEZ",K22&" "&I22,IF(J22="BÜYÜKŞEHİR",K22&" "&J22&" "&I22,J22&" "&I22&" "&K22)) -> KARICIK BELEDİYE BAŞKANLIĞI ADIYAMAN | M22: =IF(J22="MERKEZ",K22,IF(J22="BÜYÜKŞEHİR",K22&" BÜYÜKŞEHİR",J22)) -> KARICIK
A23: KESMETEPE / ADIYAMAN | B23: DENİZBANK | C23: BESNİ ŞB. | D23: 134 | E23: 90001 | F23: TR590013400001723064700003 | G23: =LEN(F23) -> 26 | H23: =IF(ISERROR(VLOOKUP(A23,Excel4!D:J,7,0)),0,VLOOKUP(A23,Excel4!D:J,7,0)) -> 0 | I23: BELEDİYE BAŞKANLIĞI | J23: KESMETEPE | K23: ADIYAMAN | L23: =IF(J23="MERKEZ",K23&" "&I23,IF(J23="BÜYÜKŞEHİR",K23&" "&J23&" "&I23,J23&" "&I23&" "&K23)) -> KESMETEPE BELEDİYE BAŞKANLIĞI ADIYAMAN | M23: =IF(J23="MERKEZ",K23,IF(J23="BÜYÜKŞEHİR",K23&" BÜYÜKŞEHİR",J23)) -> KESMETEPE
A24: KÖMÜR / ADIYAMAN | B24: HALKBANKASI | C24: ADIYAMAN ŞB. | D24: 12 | E24: 90001 | F24: TR360001200918100007000014 | G24: =LEN(F24) -> 26 | H24: =IF(ISERROR(VLOOKUP(A24,Excel4!D:J,7,0)),0,VLOOKUP(A24,Excel4!D:J,7,0)) -> 0 | I24: BELEDİYE BAŞKANLIĞI | J24: KÖMÜR | K24: ADIYAMAN | L24: =IF(J24="MERKEZ",K24&" "&I24,IF(J24="BÜYÜKŞEHİR",K24&" "&J24&" "&I24,J24&" "&I24&" "&K24)) -> KÖMÜR BELEDİYE BAŞKANLIĞI ADIYAMAN | M24: =IF(J24="MERKEZ",K24,IF(J24="BÜYÜKŞEHİR",K24&" BÜYÜKŞEHİR",J24)) -> KÖMÜR
A25: MERKEZ / ADIYAMAN | B25: HALKBANKASI | C25: MERKEZ | D25: 12 | E25: 90001 | F25: TR690001200918100007000002 | G25: =LEN(F25) -> 26 | H25: =IF(ISERROR(VLOOKUP(A25,Excel4!D:J,7,0)),0,VLOOKUP(A25,Excel4!D:J,7,0)) -> 2603.94 | I25: BELEDİYE BAŞKANLIĞI | J25: MERKEZ | K25: ADIYAMAN | L25: =IF(J25="MERKEZ",K25&" "&I25,IF(J25="BÜYÜKŞEHİR",K25&" "&J25&" "&I25,J25&" "&I25&" "&K25)) -> ADIYAMAN BELEDİYE BAŞKANLIĞI | M25: =IF(J25="MERKEZ",K25,IF(J25="BÜYÜKŞEHİR",K25&" BÜYÜKŞEHİR",J25)) -> ADIYAMAN | N25: =_xlfn.XLOOKUP(M25,[1]Sheet1!$C:$C,[1]Sheet1!$G:$G) -> #N/A
A26: SAMSAT / ADIYAMAN | B26: ZİRAAT BANKASI | C26: SAMSAT | D26: 10 | E26: 90001 | F26: TR880001000689255305595002 | G26: =LEN(F26) -> 26 | H26: =IF(ISERROR(VLOOKUP(A26,Excel4!D:J,7,0)),0,VLOOKUP(A26,Excel4!D:J,7,0)) -> 0 | I26: BELEDİYE BAŞKANLIĞI | J26: SAMSAT | K26: ADIYAMAN | L26: =IF(J26="MERKEZ",K26&" "&I26,IF(J26="BÜYÜKŞEHİR",K26&" "&J26&" "&I26,J26&" "&I26&" "&K26)) -> SAMSAT BELEDİYE BAŞKANLIĞI ADIYAMAN | M26: =IF(J26="MERKEZ",K26,IF(J26="BÜYÜKŞEHİR",K26&" BÜYÜKŞEHİR",J26)) -> SAMSAT
A27: SİNCİK / ADIYAMAN | B27: HALKBANKASI | C27: SİNCİK | D27: 12 | E27: 90001 | F27: TR130001200125400007000002 | G27: =LEN(F27) -> 26 | H27: =IF(ISERROR(VLOOKUP(A27,Excel4!D:J,7,0)),0,VLOOKUP(A27,Excel4!D:J,7,0)) -> 0 | I27: BELEDİYE BAŞKANLIĞI | J27: SİNCİK | K27: ADIYAMAN | L27: =IF(J27="MERKEZ",K27&" "&I27,IF(J27="BÜYÜKŞEHİR",K27&" "&J27&" "&I27,J27&" "&I27&" "&K27)) -> SİNCİK BELEDİYE BAŞKANLIĞI ADIYAMAN | M27: =IF(J27="MERKEZ",K27,IF(J27="BÜYÜKŞEHİR",K27&" BÜYÜKŞEHİR",J27)) -> SİNCİK | N27: =_xlfn.XLOOKUP(M27,[1]Sheet1!$A:$A,[1]Sheet1!$G:$G) -> 0
A28: ŞAMBAYAT / ADIYAMAN | B28: HALKBANKASI | C28: BESNİ | D28: 12 | E28: 90001 | F28: TR310001200918200007000099 | G28: =LEN(F28) -> 26 | H28: =IF(ISERROR(VLOOKUP(A28,Excel4!D:J,7,0)),0,VLOOKUP(A28,Excel4!D:J,7,0)) -> 0 | I28: BELEDİYE BAŞKANLIĞI | J28: ŞAMBAYAT | K28: ADIYAMAN | L28: =IF(J28="MERKEZ",K28&" "&I28,IF(J28="BÜYÜKŞEHİR",K28&" "&J28&" "&I28,J28&" "&I28&" "&K28)) -> ŞAMBAYAT BELEDİYE BAŞKANLIĞI ADIYAMAN | M28: =IF(J28="MERKEZ",K28,IF(J28="BÜYÜKŞEHİR",K28&" BÜYÜKŞEHİR",J28)) -> ŞAMBAYAT
A29: TUT / ADIYAMAN | B29: HALKBANKASI | C29: GÖLBAŞI | D29: 12 | E29: 90001 | F29: TR390001200125600007000009 | G29: =LEN(F29) -> 26 | H29: =IF(ISERROR(VLOOKUP(A29,Excel4!D:J,7,0)),0,VLOOKUP(A29,Excel4!D:J,7,0)) -> 0 | I29: BELEDİYE BAŞKANLIĞI | J29: TUT | K29: ADIYAMAN | L29: =IF(J29="MERKEZ",K29&" "&I29,IF(J29="BÜYÜKŞEHİR",K29&" "&J29&" "&I29,J29&" "&I29&" "&K29)) -> TUT BELEDİYE BAŞKANLIĞI ADIYAMAN | M29: =IF(J29="MERKEZ",K29,IF(J29="BÜYÜKŞEHİR",K29&" BÜYÜKŞEHİR",J29)) -> TUT
A30: YAYLAKONAK / ADIYAMAN | B30: HALKBANKASI | C30: ADIYAMAN MERKEZ ŞB. | D30: 12 | E30: 90001 | F30: TR950001200918100007000019 | G30: =LEN(F30) -> 26 | H30: =IF(ISERROR(VLOOKUP(A30,Excel4!D:J,7,0)),0,VLOOKUP(A30,Excel4!D:J,7,0)) -> 0 | I30: BELEDİYE BAŞKANLIĞI | J30: YAYLAKONAK | K30: ADIYAMAN | L30: =IF(J30="MERKEZ",K30&" "&I30,IF(J30="BÜYÜKŞEHİR",K30&" "&J30&" "&I30,J30&" "&I30&" "&K30)) -> YAYLAKONAK BELEDİYE BAŞKANLIĞI ADIYAMAN | M30: =IF(J30="MERKEZ",K30,IF(J30="BÜYÜKŞEHİR",K30&" BÜYÜKŞEHİR",J30)) -> YAYLAKONAK
A31: AKHARIM / AFYONKARAHİSAR | B31: ZİRAAT BANKASI | C31: SANDIKLI | D31: 10 | E31: 90001 | F31: TR850001000024336841785001 | G31: =LEN(F31) -> 26 | H31: =IF(ISERROR(VLOOKUP(A31,Excel4!D:J,7,0)),0,VLOOKUP(A31,Excel4!D:J,7,0)) -> 0 | I31: BELEDİYE BAŞKANLIĞI | J31: AKHARIM | K31: AFYON | L31: =IF(J31="MERKEZ",K31&" "&I31,IF(J31="BÜYÜKŞEHİR",K31&" "&J31&" "&I31,J31&" "&I31&" "&K31)) -> AKHARIM BELEDİYE BAŞKANLIĞI AFYON | M31: =IF(J31="MERKEZ",K31,IF(J31="BÜYÜKŞEHİR",K31&" BÜYÜKŞEHİR",J31)) -> AKHARIM
A32: AKÖREN / AFYONKARAHİSAR | B32: ZİRAAT BANKASI | C32: SİNANPAŞA | D32: 10 | E32: 90001 | F32: TR200001000517325702945001 | G32: =LEN(F32) -> 26 | H32: =IF(ISERROR(VLOOKUP(A32,Excel4!D:J,7,0)),0,VLOOKUP(A32,Excel4!D:J,7,0)) -> 0 | I32: BELEDİYE BAŞKANLIĞI | J32: AKÖREN | K32: AFYON | L32: =IF(J32="MERKEZ",K32&" "&I32,IF(J32="BÜYÜKŞEHİR",K32&" "&J32&" "&I32,J32&" "&I32&" "&K32)) -> AKÖREN BELEDİYE BAŞKANLIĞI AFYON | M32: =IF(J32="MERKEZ",K32,IF(J32="BÜYÜKŞEHİR",K32&" BÜYÜKŞEHİR",J32)) -> AKÖREN
A33: BAŞMAKÇI / AFYONKARAHİSAR | B33: ZİRAAT BANKASI | C33: BAŞMAKÇI | D33: 10 | E33: 90001 | F33: TR900001000786067327855001 | G33: =LEN(F33) -> 26 | H33: =IF(ISERROR(VLOOKUP(A33,Excel4!D:J,7,0)),0,VLOOKUP(A33,Excel4!D:J,7,0)) -> 0 | I33: BELEDİYE BAŞKANLIĞI | J33: BAŞMAKÇI | K33: AFYON | L33: =IF(J33="MERKEZ",K33&" "&I33,IF(J33="BÜYÜKŞEHİR",K33&" "&J33&" "&I33,J33&" "&I33&" "&K33)) -> BAŞMAKÇI BELEDİYE BAŞKANLIĞI AFYON | M33: =IF(J33="MERKEZ",K33,IF(J33="BÜYÜKŞEHİR",K33&" BÜYÜKŞEHİR",J33)) -> BAŞMAKÇI | N33: =_xlfn.XLOOKUP(M33,[1]Sheet1!$A:$A,[1]Sheet1!$G:$G) -> 0
A34: BAYAT / AFYONKARAHİSAR | B34: ZİRAAT BANKASI | C34: BAYAT | D34: 10 | E34: 90001 | F34: TR150001000971278317465001 | G34: =LEN(F34) -> 26 | H34: =IF(ISERROR(VLOOKUP(A34,Excel4!D:J,7,0)),0,VLOOKUP(A34,Excel4!D:J,7,0)) -> 0 | I34: BELEDİYE BAŞKANLIĞI | J34: BAYAT | K34: AFYON | L34: =IF(J34="MERKEZ",K34&" "&I34,IF(J34="BÜYÜKŞEHİR",K34&" "&J34&" "&I34,J34&" "&I34&" "&K34)) -> BAYAT BELEDİYE BAŞKANLIĞI AFYON | M34: =IF(J34="MERKEZ",K34,IF(J34="BÜYÜKŞEHİR",K34&" BÜYÜKŞEHİR",J34)) -> BAYAT
A35: BEYYAZI / AFYONKARAHİSAR | B35: ZİRAAT BANKASI | C35: MERKEZ | D35: 10 | E35: 90001 | F35: TR100001000021364301565001 | G35: =LEN(F35) -> 26 | H35: =IF(ISERROR(VLOOKUP(A35,Excel4!D:J,7,0)),0,VLOOKUP(A35,Excel4!D:J,7,0)) -> 0 | I35: BELEDİYE BAŞKANLIĞI | J35: BEYYAZI | K35: AFYON | L35: =IF(J35="MERKEZ",K35&" "&I35,IF(J35="BÜYÜKŞEHİR",K35&" "&J35&" "&I35,J35&" "&I35&" "&K35)) -> BEYYAZI BELEDİYE BAŞKANLIĞI AFYON | M35: =IF(J35="MERKEZ",K35,IF(J35="BÜYÜKŞEHİR",K35&" BÜYÜKŞEHİR",J35)) -> BEYYAZI
A36: BOLVADİN / AFYONKARAHİSAR | B36: HALKBANKASI | C36: BOLVADİN | D36: 12 | E36: 90001 | F36: TR460001200918600007000003 | G36: =LEN(F36) -> 26 | H36: =IF(ISERROR(VLOOKUP(A36,Excel4!D:J,7,0)),0,VLOOKUP(A36,Excel4!D:J,7,0)) -> 66.94 | I36: BELEDİYE BAŞKANLIĞI | J36: BOLVADİN | K36: AFYON | L36: =IF(J36="MERKEZ",K36&" "&I36,IF(J36="BÜYÜKŞEHİR",K36&" "&J36&" "&I36,J36&" "&I36&" "&K36)) -> BOLVADİN BELEDİYE BAŞKANLIĞI AFYON | M36: =IF(J36="MERKEZ",K36,IF(J36="BÜYÜKŞEHİR",K36&" BÜYÜKŞEHİR",J36)) -> BOLVADİN | N36: =_xlfn.XLOOKUP(M36,[1]Sheet1!$C:$C,[1]Sheet1!$G:$G) -> #N/A
A37: BÜYÜKKALECİK / AFYONKARAHİSAR | B37: VAKIFBANK | C37: MERKEZ | D37: 15 | E37: 90001 | F37: TR610001500158007292262225 | G37: =LEN(F37) -> 26 | H37: =IF(ISERROR(VLOOKUP(A37,Excel4!D:J,7,0)),0,VLOOKUP(A37,Excel4!D:J,7,0)) -> 0 | I37: BELEDİYE BAŞKANLIĞI | J37: BÜYÜKKALECİK | K37: AFYON | L37: =IF(J37="MERKEZ",K37&" "&I37,IF(J37="BÜYÜKŞEHİR",K37&" "&J37&" "&I37,J37&" "&I37&" "&K37)) -> BÜYÜKKALECİK BELEDİYE BAŞKANLIĞI AFYON | M37: =IF(J37="MERKEZ",K37,IF(J37="BÜYÜKŞEHİR",K37&" BÜYÜKŞEHİR",J37)) -> BÜYÜKKALECİK
A38: ÇAY / AFYONKARAHİSAR | B38: HALKBANKASI | C38: ÇAY | D38: 12 | E38: 90001 | F38: TR940001200918800007000002 | G38: =LEN(F38) -> 26 | H38: =IF(ISERROR(VLOOKUP(A38,Excel4!D:J,7,0)),0,VLOOKUP(A38,Excel4!D:J,7,0)) -> 5176.35 | I38: BELEDİYE BAŞKANLIĞI | J38: ÇAY | K38: AFYON | L38: =IF(J38="MERKEZ",K38&" "&I38,IF(J38="BÜYÜKŞEHİR",K38&" "&J38&" "&I38,J38&" "&I38&" "&K38)) -> ÇAY BELEDİYE BAŞKANLIĞI AFYON | M38: =IF(J38="MERKEZ",K38,IF(J38="BÜYÜKŞEHİR",K38&" BÜYÜKŞEHİR",J38)) -> ÇAY
A39: ÇAYIRBAĞ / AFYONKARAHİSAR | B39: ZİRAAT BANKASI | C39: ORGANİZE SANAYİ | D39: 10 | E39: 90001 | F39: TR070001002067364301335006 | G39: =LEN(F39) -> 26 | H39: =IF(ISERROR(VLOOKUP(A39,Excel4!D:J,7,0)),0,VLOOKUP(A39,Excel4!D:J,7,0)) -> 0 | I39: BELEDİYE BAŞKANLIĞI | J39: ÇAYIRBAĞ | K39: AFYON | L39: =IF(J39="MERKEZ",K39&" "&I39,IF(J39="BÜYÜKŞEHİR",K39&" "&J39&" "&I39,J39&" "&I39&" "&K39)) -> ÇAYIRBAĞ BELEDİYE BAŞKANLIĞI AFYON | M39: =IF(J39="MERKEZ",K39,IF(J39="BÜYÜKŞEHİR",K39&" BÜYÜKŞEHİR",J39)) -> ÇAYIRBAĞ
A40: ÇIKRIK / AFYONKARAHİSAR | B40: HALKBANK | C40: ORGANİZE SANAYİ ŞB | D40: 12 | E40: 90001 | F40: TR490001200918900007000031 | G40: =LEN(F40) -> 26 | H40: =IF(ISERROR(VLOOKUP(A40,Excel4!D:J,7,0)),0,VLOOKUP(A40,Excel4!D:J,7,0)) -> 0 | I40: BELEDİYE BAŞKANLIĞI | J40: ÇIKRIK | K40: AFYON | L40: =IF(J40="MERKEZ",K40&" "&I40,IF(J40="BÜYÜKŞEHİR",K40&" "&J40&" "&I40,J40&" "&I40&" "&K40)) -> ÇIKRIK BELEDİYE BAŞKANLIĞI AFYON | M40: =IF(J40="MERKEZ",K40,IF(J40="BÜYÜKŞEHİR",K40&" BÜYÜKŞEHİR",J40)) -> ÇIKRIK
...

Sheet Excel5
A1: SIRA | B1: BELEDİYE | C1: İL | D1: ÜRETİM.BİNA | E1: ÜRT.MUHT. | F1: B+M | G1: İPTAL.BİNA | H1: İPTAL.MUHT. | I1: B+M(İP) | J1: GYSV | K1: MYSV | L1: YSVG | M1: YSVM | N1: NET PRİM | O1: YSV
A2: 1 | B2: ADANA BÜYÜKŞEHİR | C2: ADANA | D2: 174202.41 | E2: 154813.22 | F2: =D2+E2 -> 329015.63 | G2: 10663.7 | H2: 13590.9 | I2: =G2+H2 -> 24254.6 | J2: =D2-G2 -> 163538.71 | K2: =E2-H2 -> 141222.32 | L2: =J2*0.1 -> 16353.871 | M2: =K2*0.1 -> 14122.232 | N2: =F2-I2 -> 304761.03 | O2: =N2*0.1 -> 30476.103 | Q2: =TEXT(D2,"#.###,00") -> 174.202,41 | R2: =TEXT(E2,"#.###,00") -> 154.813,22 | S2: =TEXT(F2,"#.###,00") -> 329.015,63 | T2: =TEXT(G2,"#.###,00") -> 10.663,70 | U2: =TEXT(H2,"#.###,00") -> 13.590,90 | V2: =TEXT(I2,"#.###,00") -> 24.254,60 | W2: =TEXT(J2,"#.###,00") -> 163.538,71 | X2: =TEXT(K2,"#.###,00") -> 141.222,32 | ... AB2: =TEXT(O2,"#.###,00") -> 30.476,10
A3: 2 | B3: MERKEZ | C3: ADIYAMAN | D3: 12248.3 | E3: 15964.6 | F3: =D3+E3 -> 28212.9 | G3: 802.4 | H3: 1371.1 | I3: =G3+H3 -> 2173.5 | J3: =D3-G3 -> 11445.9 | K3: =E3-H3 -> 14593.5 | L3: =J3*0.1 -> 1144.59 | M3: =K3*0.1 -> 1459.35 | N3: =F3-I3 -> 26039.4 | O3: =N3*0.1 -> 2603.94 | Q3: =TEXT(D3,"#.###,00") -> 12.248,30 | R3: =TEXT(E3,"#.###,00") -> 15.964,60 | S3: =TEXT(F3,"#.###,00") -> 28.212,90 | T3: =TEXT(G3,"#.###,00") -> 802,40 | U3: =TEXT(H3,"#.###,00") -> 1.371,10 | V3: =TEXT(I3,"#.###,00") -> 2.173,50 | W3: =TEXT(J3,"#.###,00") -> 11.445,90 | X3: =TEXT(K3,"#.###,00") -> 14.593,50 | ... AB3: =TEXT(O3,"#.###,00") -> 2.603,94
A4: 3 | B4: KAHTA | C4: ADIYAMAN | D4: 1905.1 | E4: 3151.8 | F4: =D4+E4 -> 5056.9 | G4: 0 | H4: 0 | I4: =G4+H4 -> 0 | J4: =D4-G4 -> 1905.1 | K4: =E4-H4 -> 3151.8 | L4: =J4*0.1 -> 190.51 | M4: =K4*0.1 -> 315.18 | N4: =F4-I4 -> 5056.9 | O4: =N4*0.1 -> 505.69 | Q4: =TEXT(D4,"#.###,00") -> 1.905,10 | R4: =TEXT(E4,"#.###,00") -> 3.151,80 | S4: =TEXT(F4,"#.###,00") -> 5.056,90 | T4: =TEXT(G4,"#.###,00") -> ,00 | U4: =TEXT(H4,"#.###,00") -> ,00 | V4: =TEXT(I4,"#.###,00") -> ,00 | W4: =TEXT(J4,"#.###,00") -> 1.905,10 | X4: =TEXT(K4,"#.###,00") -> 3.151,80 | ... AB4: =TEXT(O4,"#.###,00") -> 505,69
A5: 4 | B5: BESNİ | C5: ADIYAMAN | D5: 261.1 | E5: 449.6 | F5: =D5+E5 -> 710.7 | G5: 0 | H5: 0 | I5: =G5+H5 -> 0 | J5: =D5-G5 -> 261.1 | K5: =E5-H5 -> 449.6 | L5: =J5*0.1 -> 26.11 | M5: =K5*0.1 -> 44.96 | N5: =F5-I5 -> 710.7 | O5: =N5*0.1 -> 71.07 | Q5: =TEXT(D5,"#.###,00") -> 261,10 | R5: =TEXT(E5,"#.###,00") -> 449,60 | S5: =TEXT(F5,"#.###,00") -> 710,70 | T5: =TEXT(G5,"#.###,00") -> ,00 | U5: =TEXT(H5,"#.###,00") -> ,00 | V5: =TEXT(I5,"#.###,00") -> ,00 | W5: =TEXT(J5,"#.###,00") -> 261,10 | X5: =TEXT(K5,"#.###,00") -> 449,60 | ... AB5: =TEXT(O5,"#.###,00") -> 71,07
A6: 5 | B6: ÇELİKHAN | C6: ADIYAMAN | D6: 307.4 | E6: 118 | F6: =D6+E6 -> 425.4 | G6: 0 | H6: 0 | I6: =G6+H6 -> 0 | J6: =D6-G6 -> 307.4 | K6: =E6-H6 -> 118 | L6: =J6*0.1 -> 30.74 | M6: =K6*0.1 -> 11.8 | N6: =F6-I6 -> 425.4 | O6: =N6*0.1 -> 42.54 | Q6: =TEXT(D6,"#.###,00") -> 307,40 | R6: =TEXT(E6,"#.###,00") -> 118,00 | S6: =TEXT(F6,"#.###,00") -> 425,40 | T6: =TEXT(G6,"#.###,00") -> ,00 | U6: =TEXT(H6,"#.###,00") -> ,00 | V6: =TEXT(I6,"#.###,00") -> ,00 | W6: =TEXT(J6,"#.###,00") -> 307,40 | X6: =TEXT(K6,"#.###,00") -> 118,00 | ... AB6: =TEXT(O6,"#.###,00") -> 42,54
A7: 6 | B7: GÖLBAŞI | C7: ADIYAMAN | D7: 88.6 | E7: 134.3 | F7: =D7+E7 -> 222.9 | G7: 0 | H7: 0 | I7: =G7+H7 -> 0 | J7: =D7-G7 -> 88.6 | K7: =E7-H7 -> 134.3 | L7: =J7*0.1 -> 8.86 | M7: =K7*0.1 -> 13.43 | N7: =F7-I7 -> 222.9 | O7: =N7*0.1 -> 22.29 | Q7: =TEXT(D7,"#.###,00") -> 88,60 | R7: =TEXT(E7,"#.###,00") -> 134,30 | S7: =TEXT(F7,"#.###,00") -> 222,90 | T7: =TEXT(G7,"#.###,00") -> ,00 | U7: =TEXT(H7,"#.###,00") -> ,00 | V7: =TEXT(I7,"#.###,00") -> ,00 | W7: =TEXT(J7,"#.###,00") -> 88,60 | X7: =TEXT(K7,"#.###,00") -> 134,30 | ... AB7: =TEXT(O7,"#.###,00") -> 22,29
A8: 7 | B8: MERKEZ | C8: AFYONKARAHİSAR | D8: 30076.5 | E8: 55308.7 | F8: =D8+E8 -> 85385.2 | G8: 344 | H8: 282.9 | I8: =G8+H8 -> 626.9 | J8: =D8-G8 -> 29732.5 | K8: =E8-H8 -> 55025.8 | L8: =J8*0.1 -> 2973.25 | M8: =K8*0.1 -> 5502.58 | N8: =F8-I8 -> 84758.3 | O8: =N8*0.1 -> 8475.83 | Q8: =TEXT(D8,"#.###,00") -> 30.076,50 | R8: =TEXT(E8,"#.###,00") -> 55.308,70 | S8: =TEXT(F8,"#.###,00") -> 85.385,20 | T8: =TEXT(G8,"#.###,00") -> 344,00 | U8: =TEXT(H8,"#.###,00") -> 282,90 | V8: =TEXT(I8,"#.###,00") -> 626,90 | W8: =TEXT(J8,"#.###,00") -> 29.732,50 | X8: =TEXT(K8,"#.###,00") -> 55.025,80 | ... AB8: =TEXT(O8,"#.###,00") -> 8.475,83
A9: 8 | B9: ÇAY | C9: AFYONKARAHİSAR | D9: 51763.5 | F9: =D9+E9 -> 51763.5 | G9: 0 | I9: =G9+H9 -> 0 | J9: =D9-G9 -> 51763.5 | K9: =E9-H9 -> 0 | L9: =J9*0.1 -> 5176.35 | M9: =K9*0.1 -> 0 | N9: =F9-I9 -> 51763.5 | O9: =N9*0.1 -> 5176.35 | Q9: =TEXT(D9,"#.###,00") -> 51.763,50 | R9: =TEXT(E9,"#.###,00") -> ,00 | S9: =TEXT(F9,"#.###,00") -> 51.763,50 | T9: =TEXT(G9,"#.###,00") -> ,00 | U9: =TEXT(H9,"#.###,00") -> ,00 | V9: =TEXT(I9,"#.###,00") -> ,00 | W9: =TEXT(J9,"#.###,00") -> 51.763,50 | X9: =TEXT(K9,"#.###,00") -> ,00 | ... AB9: =TEXT(O9,"#.###,00") -> 5.176,35
A10: 9 | B10: ŞUHUT | C10: AFYONKARAHİSAR | D10: 4257 | E10: 1005.5 | F10: =D10+E10 -> 5262.5 | G10: 0 | H10: 0 | I10: =G10+H10 -> 0 | J10: =D10-G10 -> 4257 | K10: =E10-H10 -> 1005.5 | L10: =J10*0.1 -> 425.7 | M10: =K10*0.1 -> 100.55 | N10: =F10-I10 -> 5262.5 | O10: =N10*0.1 -> 526.25 | Q10: =TEXT(D10,"#.###,00") -> 4.257,00 | R10: =TEXT(E10,"#.###,00") -> 1.005,50 | S10: =TEXT(F10,"#.###,00") -> 5.262,50 | T10: =TEXT(G10,"#.###,00") -> ,00 | U10: =TEXT(H10,"#.###,00") -> ,00 | V10: =TEXT(I10,"#.###,00") -> ,00 | W10: =TEXT(J10,"#.###,00") -> 4.257,00 | X10: =TEXT(K10,"#.###,00") -> 1.005,50 | ... AB10: =TEXT(O10,"#.###,00") -> 526,25
A11: 10 | B11: İSCEHİSAR | C11: AFYONKARAHİSAR | D11: 2151.9 | E11: 199.1 | F11: =D11+E11 -> 2351 | G11: 0 | H11: 0 | I11: =G11+H11 -> 0 | J11: =D11-G11 -> 2151.9 | K11: =E11-H11 -> 199.1 | L11: =J11*0.1 -> 215.19 | M11: =K11*0.1 -> 19.91 | N11: =F11-I11 -> 2351 | O11: =N11*0.1 -> 235.1 | Q11: =TEXT(D11,"#.###,00") -> 2.151,90 | R11: =TEXT(E11,"#.###,00") -> 199,10 | S11: =TEXT(F11,"#.###,00") -> 2.351,00 | T11: =TEXT(G11,"#.###,00") -> ,00 | U11: =TEXT(H11,"#.###,00") -> ,00 | V11: =TEXT(I11,"#.###,00") -> ,00 | W11: =TEXT(J11,"#.###,00") -> 2.151,90 | X11: =TEXT(K11,"#.###,00") -> 199,10 | ... AB11: =TEXT(O11,"#.###,00") -> 235,10
A12: 11 | B12: DİNAR | C12: AFYONKARAHİSAR | D12: 890.4 | E12: 1468.4 | F12: =D12+E12 -> 2358.8 | G12: 21.7 | H12: 12.1 | I12: =G12+H12 -> 33.8 | J12: =D12-G12 -> 868.7 | K12: =E12-H12 -> 1456.3 | L12: =J12*0.1 -> 86.87 | M12: =K12*0.1 -> 145.63 | N12: =F12-I12 -> 2325 | O12: =N12*0.1 -> 232.5 | Q12: =TEXT(D12,"#.###,00") -> 890,40 | R12: =TEXT(E12,"#.###,00") -> 1.468,40 | S12: =TEXT(F12,"#.###,00") -> 2.358,80 | T12: =TEXT(G12,"#.###,00") -> 21,70 | U12: =TEXT(H12,"#.###,00") -> 12,10 | V12: =TEXT(I12,"#.###,00") -> 33,80 | W12: =TEXT(J12,"#.###,00") -> 868,70 | X12: =TEXT(K12,"#.###,00") -> 1.456,30 | ... AB12: =TEXT(O12,"#.###,00") -> 232,50
A13: 12 | B13: DAZKIRI | C13: AFYONKARAHİSAR | D13: 0.2 | E13: 2049.3 | F13: =D13+E13 -> 2049.5 | G13: 0 | H13: 0 | I13: =G13+H13 -> 0 | J13: =D13-G13 -> 0.2 | K13: =E13-H13 -> 2049.3 | L13: =J13*0.1 -> 0.02 | M13: =K13*0.1 -> 204.93 | N13: =F13-I13 -> 2049.5 | O13: =N13*0.1 -> 204.95 | Q13: =TEXT(D13,"#.###,00") -> ,20 | R13: =TEXT(E13,"#.###,00") -> 2.049,30 | S13: =TEXT(F13,"#.###,00") -> 2.049,50 | T13: =TEXT(G13,"#.###,00") -> ,00 | U13: =TEXT(H13,"#.###,00") -> ,00 | V13: =TEXT(I13,"#.###,00") -> ,00 | W13: =TEXT(J13,"#.###,00") -> ,20 | X13: =TEXT(K13,"#.###,00") -> 2.049,30 | ... AB13: =TEXT(O13,"#.###,00") -> 204,95
A14: 13 | B14: İHSANİYE | C14: AFYONKARAHİSAR | D14: 0.1 | E14: 1335.8 | F14: =D14+E14 -> 1335.9 | G14: 0 | H14: 0 | I14: =G14+H14 -> 0 | J14: =D14-G14 -> 0.1 | K14: =E14-H14 -> 1335.8 | L14: =J14*0.1 -> 0.01 | M14: =K14*0.1 -> 133.58 | N14: =F14-I14 -> 1335.9 | O14: =N14*0.1 -> 133.59 | Q14: =TEXT(D14,"#.###,00") -> ,10 | R14: =TEXT(E14,"#.###,00") -> 1.335,80 | S14: =TEXT(F14,"#.###,00") -> 1.335,90 | T14: =TEXT(G14,"#.###,00") -> ,00 | U14: =TEXT(H14,"#.###,00") -> ,00 | V14: =TEXT(I14,"#.###,00") -> ,00 | W14: =TEXT(J14,"#.###,00") -> ,10 | X14: =TEXT(K14,"#.###,00") -> 1.335,80 | ... AB14: =TEXT(O14,"#.###,00") -> 133,59
A15: 14 | B15: SULTANDAĞI | C15: AFYONKARAHİSAR | D15: 688.6 | E15: 478.1 | F15: =D15+E15 -> 1166.7 | G15: 0 | H15: 0 | I15: =G15+H15 -> 0 | J15: =D15-G15 -> 688.6 | K15: =E15-H15 -> 478.1 | L15: =J15*0.1 -> 68.86 | M15: =K15*0.1 -> 47.81 | N15: =F15-I15 -> 1166.7 | O15: =N15*0.1 -> 116.67 | Q15: =TEXT(D15,"#.###,00") -> 688,60 | R15: =TEXT(E15,"#.###,00") -> 478,10 | S15: =TEXT(F15,"#.###,00") -> 1.166,70 | T15: =TEXT(G15,"#.###,00") -> ,00 | U15: =TEXT(H15,"#.###,00") -> ,00 | V15: =TEXT(I15,"#.###,00") -> ,00 | W15: =TEXT(J15,"#.###,00") -> 688,60 | X15: =TEXT(K15,"#.###,00") -> 478,10 | ... AB15: =TEXT(O15,"#.###,00") -> 116,67
A16: 15 | B16: EMİRDAĞ | C16: AFYONKARAHİSAR | D16: 909.3 | E16: 256.5 | F16: =D16+E16 -> 1165.8 | G16: 23.3 | H16: 0 | I16: =G16+H16 -> 23.3 | J16: =D16-G16 -> 886 | K16: =E16-H16 -> 256.5 | L16: =J16*0.1 -> 88.6 | M16: =K16*0.1 -> 25.65 | N16: =F16-I16 -> 1142.5 | O16: =N16*0.1 -> 114.25 | Q16: =TEXT(D16,"#.###,00") -> 909,30 | R16: =TEXT(E16,"#.###,00") -> 256,50 | S16: =TEXT(F16,"#.###,00") -> 1.165,80 | T16: =TEXT(G16,"#.###,00") -> 23,30 | U16: =TEXT(H16,"#.###,00") -> ,00 | V16: =TEXT(I16,"#.###,00") -> 23,30 | W16: =TEXT(J16,"#.###,00") -> 886,00 | X16: =TEXT(K16,"#.###,00") -> 256,50 | ... AB16: =TEXT(O16,"#.###,00") -> 114,25
A17: 16 | B17: SANDIKLI | C17: AFYONKARAHİSAR | D17: 207.2 | E17: 569.4 | F17: =D17+E17 -> 776.6 | G17: 0 | H17: 0 | I17: =G17+H17 -> 0 | J17: =D17-G17 -> 207.2 | K17: =E17-H17 -> 569.4 | L17: =J17*0.1 -> 20.72 | M17: =K17*0.1 -> 56.94 | N17: =F17-I17 -> 776.6 | O17: =N17*0.1 -> 77.66 | Q17: =TEXT(D17,"#.###,00") -> 207,20 | R17: =TEXT(E17,"#.###,00") -> 569,40 | S17: =TEXT(F17,"#.###,00") -> 776,60 | T17: =TEXT(G17,"#.###,00") -> ,00 | U17: =TEXT(H17,"#.###,00") -> ,00 | V17: =TEXT(I17,"#.###,00") -> ,00 | W17: =TEXT(J17,"#.###,00") -> 207,20 | X17: =TEXT(K17,"#.###,00") -> 569,40 | ... AB17: =TEXT(O17,"#.###,00") -> 77,66
A18: 17 | B18: SİNANPAŞA | C18: AFYONKARAHİSAR | D18: 487.9 | E18: 1075.5 | F18: =D18+E18 -> 1563.4 | G18: 0 | H18: 0 | I18: =G18+H18 -> 0 | J18: =D18-G18 -> 487.9 | K18: =E18-H18 -> 1075.5 | L18: =J18*0.1 -> 48.79 | M18: =K18*0.1 -> 107.55 | N18: =F18-I18 -> 1563.4 | O18: =N18*0.1 -> 156.34 | Q18: =TEXT(D18,"#.###,00") -> 487,90 | R18: =TEXT(E18,"#.###,00") -> 1.075,50 | S18: =TEXT(F18,"#.###,00") -> 1.563,40 | T18: =TEXT(G18,"#.###,00") -> ,00 | U18: =TEXT(H18,"#.###,00") -> ,00 | V18: =TEXT(I18,"#.###,00") -> ,00 | W18: =TEXT(J18,"#.###,00") -> 487,90 | X18: =TEXT(K18,"#.###,00") -> 1.075,50 | ... AB18: =TEXT(O18,"#.###,00") -> 156,34
A19: 18 | B19: HOCALAR | C19: AFYONKARAHİSAR | D19: 246.6 | E19: 129.8 | F19: =D19+E19 -> 376.4 | G19: 4.2 | H19: 57.2 | I19: =G19+H19 -> 61.4 | J19: =D19-G19 -> 242.4 | K19: =E19-H19 -> 72.6 | L19: =J19*0.1 -> 24.24 | M19: =K19*0.1 -> 7.26 | N19: =F19-I19 -> 315 | O19: =N19*0.1 -> 31.5 | Q19: =TEXT(D19,"#.###,00") -> 246,60 | R19: =TEXT(E19,"#.###,00") -> 129,80 | S19: =TEXT(F19,"#.###,00") -> 376,40 | T19: =TEXT(G19,"#.###,00") -> 4,20 | U19: =TEXT(H19,"#.###,00") -> 57,20 | V19: =TEXT(I19,"#.###,00") -> 61,40 | W19: =TEXT(J19,"#.###,00") -> 242,40 | X19: =TEXT(K19,"#.###,00") -> 72,60 | ... AB19: =TEXT(O19,"#.###,00") -> 31,50
A20: 19 | B20: MERKEZ | C20: AĞRI | D20: 11599.7 | E20: 2700.7 | F20: =D20+E20 -> 14300.4 | G20: 122.3 | H20: 546.9 | I20: =G20+H20 -> 669.2 | J20: =D20-G20 -> 11477.4 | K20: =E20-H20 -> 2153.8 | L20: =J20*0.1 -> 1147.74 | M20: =K20*0.1 -> 215.38 | N20: =F20-I20 -> 13631.2 | O20: =N20*0.1 -> 1363.12 | Q20: =TEXT(D20,"#.###,00") -> 11.599,70 | R20: =TEXT(E20,"#.###,00") -> 2.700,70 | S20: =TEXT(F20,"#.###,00") -> 14.300,40 | T20: =TEXT(G20,"#.###,00") -> 122,30 | U20: =TEXT(H20,"#.###,00") -> 546,90 | V20: =TEXT(I20,"#.###,00") -> 669,20 | W20: =TEXT(J20,"#.###,00") -> 11.477,40 | X20: =TEXT(K20,"#.###,00") -> 2.153,80 | ... AB20: =TEXT(O20,"#.###,00") -> 1.363,12
A21: 20 | B21: PATNOS | C21: AĞRI | D21: 6155.3 | E21: 221 | F21: =D21+E21 -> 6376.3 | G21: 255.7 | H21: 570.1 | I21: =G21+H21 -> 825.8 | J21: =D21-G21 -> 5899.6 | K21: =E21-H21 -> -349.1 | L21: =J21*0.1 -> 589.96 | M21: =K21*0.1 -> -34.91 | N21: =F21-I21 -> 5550.5 | O21: =N21*0.1 -> 555.05 | Q21: =TEXT(D21,"#.###,00") -> 6.155,30 | R21: =TEXT(E21,"#.###,00") -> 221,00 | S21: =TEXT(F21,"#.###,00") -> 6.376,30 | T21: =TEXT(G21,"#.###,00") -> 255,70 | U21: =TEXT(H21,"#.###,00") -> 570,10 | V21: =TEXT(I21,"#.###,00") -> 825,80 | W21: =TEXT(J21,"#.###,00") -> 5.899,60 | X21: =TEXT(K21,"#.###,00") -> -349,10 | ... AB21: =TEXT(O21,"#.###,00") -> 555,05
... A24: 23 | B24: SULTANHANI | C24: AKSARAY | D24: 15822.4 | E24: 10439.7 | F24: =D24+E24 -> 26262.1 | G24: 7826.9 | H24: 6006.3 | I24: =G24+H24 -> 13833.2 | J24: =D24-G24 -> 7995.5 | K24: =E24-H24 -> 4433.4 | L24: =J24*0.1 -> 799.55 | M24: =K24*0.1 -> 443.34 | N24: =F24-I24 -> 12428.9 | O24: =N24*0.1 -> 1242.89 | Q24: =TEXT(D24,"#.###,00") -> 15.822,40 | R24: =TEXT(E24,"#.###,00") -> 10.439,70 | S24: =TEXT(F24,"#.###,00") -> 26.262,10 | T24: =TEXT(G24,"#.###,00") -> 7.826,90 | U24: =TEXT(H24,"#.###,00") -> 6.006,30 | V24: =TEXT(I24,"#.###,00") -> 13.833,20 | W24: =TEXT(J24,"#.###,00") -> 7.995,50 | X24: =TEXT(K24,"#.###,00") -> 4.433,40 | ... AB24: =TEXT(O24,"#.###,00") -> 1.242,89
A25: 24 | B25: AĞAÇÖREN | C25: AKSARAY | E25: 4362.3 | F25: =D25+E25 -> 4362.3 | H25: 0 | I25: =G25+H25 -> 0 | J25: =D25-G25 -> 0 | K25: =E25-H25 -> 4362.3 | L25: =J25*0.1 -> 0 | M25: =K25*0.1 -> 436.23 | N25: =F25-I25 -> 4362.3 | O25: =N25*0.1 -> 436.23 | Q25: =TEXT(D25,"#.###,00") -> ,00 | R25: =TEXT(E25,"#.###,00") -> 4.362,30 | S25: =TEXT(F25,"#.###,00") -> 4.362,30 | T25: =TEXT(G25,"#.###,00") -> ,00 | U25: =TEXT(H25,"#.###,00") -> ,00 | V25: =TEXT(I25,"#.###,00") -> ,00 | W25: =TEXT(J25,"#.###,00") -> ,00 | X25: =TEXT(K25,"#.###,00") -> 4.362,30 | ... AB25: =TEXT(O25,"#.###,00") -> 436,23
A26: 25 | B26: ESKİL | C26: AKSARAY | D26: 551 | E26: 2947.3 | F26: =D26+E26 -> 3498.3 | G26: 110.2 | H26: 587.1 | I26: =G26+H26 -> 697.3 | J26: =D26-G26 -> 440.8 | K26: =E26-H26 -> 2360.2 | L26: =J26*0.1 -> 44.08 | M26: =K26*0.1 -> 236.02 | N26: =F26-I26 -> 2801 | O26: =N26*0.1 -> 280.1 | Q26: =TEXT(D26,"#.###,00") -> 551,00 | R26: =TEXT(E26,"#.###,00") -> 2.947,30 | S26: =TEXT(F26,"#.###,00") -> 3.498,30 | T26: =TEXT(G26,"#.###,00") -> 110,20 | U26: =TEXT(H26,"#.###,00") -> 587,10 | V26: =TEXT(I26,"#.###,00") -> 697,30 | W26: =TEXT(J26,"#.###,00") -> 440,80 | X26: =TEXT(K26,"#.###,00") -> 2.360,20 | ... AB26: =TEXT(O26,"#.###,00") -> 280,10
A27: 26 | B27: ORTAKÖY | C27: AKSARAY | D27: 310.4 | E27: 401.2 | F27: =D27+E27 -> 711.6 | G27: 0 | H27: 0 | I27: =G27+H27 -> 0 | J27: =D27-G27 -> 310.4 | K27: =E27-H27 -> 401.2 | L27: =J27*0.1 -> 31.04 | M27: =K27*0.1 -> 40.12 | N27: =F27-I27 -> 711.6 | O27: =N27*0.1 -> 71.16 | Q27: =TEXT(D27,"#.###,00") -> 310,40 | R27: =TEXT(E27,"#.###,00") -> 401,20 | S27: =TEXT(F27,"#.###,00") -> 711,60 | T27: =TEXT(G27,"#.###,00") -> ,00 | U27: =TEXT(H27,"#.###,00") -> ,00 | V27: =TEXT(I27,"#.###,00") -> ,00 | W27: =TEXT(J27,"#.###,00") -> 310,40 | X27: =TEXT(K27,"#.###,00") -> 401,20 | ... AB27: =TEXT(O27,"#.###,00") -> 71,16
A28: 27 | B28: GÜZELYURT | C28: AKSARAY | D28: 85.8 | E28: 51.9 | F28: =D28+E28 -> 137.7 | G28: 0.1 | H28: 0 | I28: =G28+H28 -> 0.1 | J28: =D28-G28 -> 85.7 | K28: =E28-H28 -> 51.9 | L28: =J28*0.1 -> 8.57 | M28: =K28*0.1 -> 5.19 | N28: =F28-I28 -> 137.6 | O28: =N28*0.1 -> 13.76 | Q28: =TEXT(D28,"#.###,00") -> 85,80 | R28: =TEXT(E28,"#.###,00") -> 51,90 | S28: =TEXT(F28,"#.###,00") -> 137,70 | T28: =TEXT(G28,"#.###,00") -> ,10 | U28: =TEXT(H28,"#.###,00") -> ,00 | V28: =TEXT(I28,"#.###,00") -> ,10 | W28: =TEXT(J28,"#.###,00") -> 85,70 | X28: =TEXT(K28,"#.###,00") -> 51,90 | ... AB28: =TEXT(O28,"#.###,00") -> 13,76
A29: 28 | B29: MERKEZ | C29: AMASYA | D29: 18996.4 | E29: 45496 | F29: =D29+E29 -> 64492.4 | G29: 173.7 | H29: 602.3 | I29: =G29+H29 -> 776 | J29: =D29-G29 -> 18822.7 | K29: =E29-H29 -> 44893.7 | L29: =J29*0.1 -> 1882.27 | M29: =K29*0.1 -> 4489.37 | N29: =F29-I29 -> 63716.4 | O29: =N29*0.1 -> 6371.64 | Q29: =TEXT(D29,"#.###,00") -> 18.996,40 | R29: =TEXT(E29,"#.###,00") -> 45.496,00 | S29: =TEXT(F29,"#.###,00") -> 64.492,40 | T29: =TEXT(G29,"#.###,00") -> 173,70 | U29: =TEXT(H29,"#.###,00") -> 602,30 | V29: =TEXT(I29,"#.###,00") -> 776,00 | W29: =TEXT(J29,"#.###,00") -> 18.822,70 | X29: =TEXT(K29,"#.###,00") -> 44.893,70 | ... AB29: =TEXT(O29,"#.###,00") -> 6.371,64
A30: 29 | B30: MERZİFON | C30: AMASYA | D30: 5248.4 | E30: 2442.3 | F30: =D30+E30 -> 7690.7 | G30: 45 | H30: 402.8 | I30: =G30+H30 -> 447.8 | J30: =D30-G30 -> 5203.4 | K30: =E30-H30 -> 2039.5 | L30: =J30*0.1 -> 520.34 | M30: =K30*0.1 -> 203.95 | N30: =F30-I30 -> 7242.9 | O30: =N30*0.1 -> 724.29 | Q30: =TEXT(D30,"#.###,00") -> 5.248,40 | R30: =TEXT(E30,"#.###,00") -> 2.442,30 | S30: =TEXT(F30,"#.###,00") -> 7.690,70 | T30: =TEXT(G30,"#.###,00") -> 45,00 | U30: =TEXT(H30,"#.###,00") -> 402,80 | V30: =TEXT(I30,"#.###,00") -> 447,80 | W30: =TEXT(J30,"#.###,00") -> 5.203,40 | X30: =TEXT(K30,"#.###,00") -> 2.039,50 | ... AB30: =TEXT(O30,"#.###,00") -> 724,29
A31: 30 | B31: GÜMÜŞHACIKÖY | C31: AMASYA | D31: 377.1 | E31: 313.3 | F31: =D31+E31 -> 690.4 | G31: 0 | H31: 0 | I31: =G31+H31 -> 0 | J31: =D31-G31 -> 377.1 | K31: =E31-H31 -> 313.3 | L31: =J31*0.1 -> 37.71 | M31: =K31*0.1 -> 31.33 | N31: =F31-I31 -> 690.4 | O31: =N31*0.1 -> 69.04 | Q31: =TEXT(D31,"#.###,00") -> 377,10 | R31: =TEXT(E31,"#.###,00") -> 313,30 | S31: =TEXT(F31,"#.###,00") -> 690,40 | T31: =TEXT(G31,"#.###,00") -> ,00 | U31: =TEXT(H31,"#.###,00") -> ,00 | V31: =TEXT(I31,"#.###,00") -> ,00 | W31: =TEXT(J31,"#.###,00") -> 377,10 | X31: =TEXT(K31,"#.###,00") -> 313,30 | ... AB31: =TEXT(O31,"#.###,00") -> 69,04
A32: 31 | B32: GÖYNÜCEK | C32: AMASYA | D32: 5.4 | E32: 103.3 | F32: =D32+E32 -> 108.7 | G32: 0 | H32: 0 | I32: =G32+H32 -> 0 | J32: =D32-G32 -> 5.4 | K32: =E32-H32 -> 103.3 | L32: =J32*0.1 -> 0.54 | M32: =K32*0.1 -> 10.33 | N32: =F32-I32 -> 108.7 | O32: =N32*0.1 -> 10.87 | Q32: =TEXT(D32,"#.###,00") -> 5,40 | R32: =TEXT(E32,"#.###,00") -> 103,30 | S32: =TEXT(F32,"#.###,00") -> 108,70 | T32: =TEXT(G32,"#.###,00") -> ,00 | U32: =TEXT(H32,"#.###,00") -> ,00 | V32: =TEXT(I32,"#.###,00") -> ,00 | W32: =TEXT(J32,"#.###,00") -> 5,40 | X32: =TEXT(K32,"#.###,00") -> 103,30 | ... AB32: =TEXT(O32,"#.###,00") -> 10,87
A33: 32 | B33: TAŞOVA | C33: AMASYA | D33: 5.4 | E33: 103.3 | F33: =D33+E33 -> 108.7 | G33: 0 | H33: 0 | I33: =G33+H33 -> 0 | J33: =D33-G33 -> 5.4 | K33: =E33-H33 -> 103.3 | L33: =J33*0.1 -> 0.54 | M33: =K33*0.1 -> 10.33 | N33: =F33-I33 -> 108.7 | O33: =N33*0.1 -> 10.87 | Q33: =TEXT(D33,"#.###,00") -> 5,40 | R33: =TEXT(E33,"#.###,00") -> 103,30 | S33: =TEXT(F33,"#.###,00") -> 108,70 | T33: =TEXT(G33,"#.###,00") -> ,00 | U33: =TEXT(H33,"#.###,00") -> ,00 | V33: =TEXT(I33,"#.###,00") -> ,00 | W33: =TEXT(J33,"#.###,00") -> 5,40 | X33: =TEXT(K33,"#.###,00") -> 103,30 | ... AB33: =TEXT(O33,"#.###,00") -> 10,87
A34: 33 | B34: SULUOVA | C34: AMASYA | D34: 207 | F34: =D34+E34 -> 207 | G34: 126.4 | I34: =G34+H34 -> 126.4 | J34: =D34-G34 -> 80.6 | K34: =E34-H34 -> 0 | L34: =J34*0.1 -> 8.06 | M34: =K34*0.1 -> 0 | N34: =F34-I34 -> 80.6 | O34: =N34*0.1 -> 8.06 | Q34: =TEXT(D34,"#.###,00") -> 207,00 | R34: =TEXT(E34,"#.###,00") -> ,00 | S34: =TEXT(F34,"#.###,00") -> 207,00 | T34: =TEXT(G34,"#.###,00") -> 126,40 | U34: =TEXT(H34,"#.###,00") -> ,00 | V34: =TEXT(I34,"#.###,00") -> 126,40 | W34: =TEXT(J34,"#.###,00") -> 80,60 | X34: =TEXT(K34,"#.###,00") -> ,00 | ... AB34: =TEXT(O34,"#.###,00") -> 8,06
A35: 34 | B35: ANKARA BÜYÜKŞEHİR | C35: ANKARA | D35: 1011237.3 | E35: 1497153.8 | F35: =D35+E35 -> 2508391.1 | G35: 51577.41 | H35: 107930.46 | I35: =G35+H35 -> 159507.87 | J35: =D35-G35 -> 959659.89 | K35: =E35-H35 -> 1389223.3 | L35: =J35*0.1 -> 95965.989 | M35: =K35*0.1 -> 138922.33 | N35: =F35-I35 -> 2348883.2 | O35: =N35*0.1 -> 234888.32 | Q35: =TEXT(D35,"#.###,00") -> 1.011.237,30 | R35: =TEXT(E35,"#.###,00") -> 1.497.153,79 | S35: =TEXT(F35,"#.###,00") -> 2.508.391,09 | T35: =TEXT(G35,"#.###,00") -> 51.577,41 | U35: =TEXT(H35,"#.###,00") -> 107.930,46 | V35: =TEXT(I35,"#.###,00") -> 159.507,87 | W35: =TEXT(J35,"#.###,00") -> 959.659,89 | X35: =TEXT(K35,"#.###,00") -> 1.389.223,33 | ... AB35: =TEXT(O35,"#.###,00") -> 234.888,32
A36: 35 | B36: ANTALYA BÜYÜKŞEHİR | C36: ANTALYA | D36: 656158.68 | E36: 1043094.9 | F36: =D36+E36 -> 1699253.6 | G36: 66212.22 | H36: 73315.48 | I36: =G36+H36 -> 139527.7 | J36: =D36-G36 -> 589946.46 | K36: =E36-H36 -> 969779.47 | L36: =J36*0.1 -> 58994.646 | M36: =K36*0.1 -> 96977.947 | N36: =F36-I36 -> 1559725.9 | O36: =N36*0.1 -> 155972.59 | Q36: =TEXT(D36,"#.###,00") -> 656.158,68 | R36: =TEXT(E36,"#.###,00") -> 1.043.094,95 | S36: =TEXT(F36,"#.###,00") -> 1.699.253,63 | T36: =TEXT(G36,"#.###,00") -> 66.212,22 | U36: =TEXT(H36,"#.###,00") -> 73.315,48 | V36: =TEXT(I36,"#.###,00") -> 139.527,70 | W36: =TEXT(J36,"#.###,00") -> 589.946,46 | X36: =TEXT(K36,"#.###,00") -> 969.779,47 | ... AB36: =TEXT(O36,"#.###,00") -> 155.972,59
A37: 36 | B37: MERKEZ | C37: ARDAHAN | D37: 4355 | E37: 2429.3 | F37: =D37+E37 -> 6784.3 | G37: 1738.6 | H37: 28.3 | I37: =G37+H37 -> 1766.9 | J37: =D37-G37 -> 2616.4 | K37: =E37-H37 -> 2401 | L37: =J37*0.1 -> 261.64 | M37: =K37*0.1 -> 240.1 | N37: =F37-I37 -> 5017.4 | O37: =N37*0.1 -> 501.74 | Q37: =TEXT(D37,"#.###,00") -> 4.355,00 | R37: =TEXT(E37,"#.###,00") -> 2.429,30 | S37: =TEXT(F37,"#.###,00") -> 6.784,30 | T37: =TEXT(G37,"#.###,00") -> 1.738,60 | U37: =TEXT(H37,"#.###,00") -> 28,30 | V37: =TEXT(I37,"#.###,00") -> 1.766,90 | W37: =TEXT(J37,"#.###,00") -> 2.616,40 | X37: =TEXT(K37,"#.###,00") -> 2.401,00 | ... AB37: =TEXT(O37,"#.###,00") -> 501,74
A38: 37 | B38: GÖLE | C38: ARDAHAN | D38: 1702.7 | E38: 502.7 | F38: =D38+E38 -> 2205.4 | G38: 0 | H38: 0 | I38: =G38+H38 -> 0 | J38: =D38-G38 -> 1702.7 | K38: =E38-H38 -> 502.7 | L38: =J38*0.1 -> 170.27 | M38: =K38*0.1 -> 50.27 | N38: =F38-I38 -> 2205.4 | O38: =N38*0.1 -> 220.54 | Q38: =TEXT(D38,"#.###,00") -> 1.702,70 | R38: =TEXT(E38,"#.###,00") -> 502,70 | S38: =TEXT(F38,"#.###,00") -> 2.205,40 | T38: =TEXT(G38,"#.###,00") -> ,00 | U38: =TEXT(H38,"#.###,00") -> ,00 | V38: =TEXT(I38,"#.###,00") -> ,00 | W38: =TEXT(J38,"#.###,00") -> 1.702,70 | X38: =TEXT(K38,"#.###,00") -> 502,70 | ... AB38: =TEXT(O38,"#.###,00") -> 220,54
A39: 38 | B39: HANAK | C39: ARDAHAN | D39: 455.8 | E39: 45.8 | F39: =D39+E39 -> 501.6 | G39: 0 | H39: 0 | I39: =G39+H39 -> 0 | J39: =D39-G39 -> 455.8 | K39: =E39-H39 -> 45.8 | L39: =J39*0.1 -> 45.58 | M39: =K39*0.1 -> 4.58 | N39: =F39-I39 -> 501.6 | O39: =N39*0.1 -> 50.16 | Q39: =TEXT(D39,"#.###,00") -> 455,80 | R39: =TEXT(E39,"#.###,00") -> 45,80 | S39: =TEXT(F39,"#.###,00") -> 501,60 | T39: =TEXT(G39,"#.###,00") -> ,00 | U39: =TEXT(H39,"#.###,00") -> ,00 | V39: =TEXT(I39,"#.###,00") -> ,00 | W39: =TEXT(J39,"#.###,00") -> 455,80 | X39: =TEXT(K39,"#.###,00") -> 45,80 | ... AB39: =TEXT(O39,"#.###,00") -> 50,16
A40: 39 | B40: POSOF | C40: ARDAHAN | D40: 4.6 | E40: 478.5 | F40: =D40+E40 -> 483.1 | G40: 0 | H40: 0 | I40: =G40+H40 -> 0 | J40: =D40-G40 -> 4.6 | K40: =E40-H40 -> 478.5 | L40: =J40*0.1 -> 0.46 | M40: =K40*0.1 -> 47.85 | N40: =F40-I40 -> 483.1 | O40: =N40*0.1 -> 48.31 | Q40: =TEXT(D40,"#.###,00") -> 4,60 | R40: =TEXT(E40,"#.###,00") -> 478,50 | S40: =TEXT(F40,"#.###,00") -> 483,10 | T40: =TEXT(G40,"#.###,00") -> ,00 | U40: =TEXT(H40,"#.###,00") -> ,00 | V40: =TEXT(I40,"#.###,00") -> ,00 | W40: =TEXT(J40,"#.###,00") -> 4,60 | X40: =TEXT(K40,"#.###,00") -> 478,50 | ... AB40: =TEXT(O40,"#.###,00") -> 48,31
A41: 40 | B41: DAMAL | C41: ARDAHAN | D41: 288.7 | E41: 186.4 | F41: =D41+E41 -> 475.1 | G41: 0 | H41: 0 | I41: =G41+H41 -> 0 | J41: =D41-G41 -> 288.7 | K41: =E41-H41 -> 186.4 | L41: =J41*0.1 -> 28.87 | M41: =K41*0.1 -> 18.64 | N41: =F41-I41 -> 475.1 | O41: =N41*0.1 -> 47.51 | Q41: =TEXT(D41,"#.###,00") -> 288,70 | R41: =TEXT(E41,"#.###,00") -> 186,40 | S41: =TEXT(F41,"#.###,00") -> 475,10 | T41: =TEXT(G41,"#.###,00") -> ,00 | U41: =TEXT(H41,"#.###,00") -> ,00 | V41: =TEXT(I41,"#.###,00") -> ,00 | W41: =TEXT(J41,"#.###,00") -> 288,70 | X41: =TEXT(K41,"#.###,00") -> 186,40 | ... AB41: =TEXT(O41,"#.###,00") -> 47,51
A42: 41 | B42: HOPA | C42: ARTVİN | D42: 2585.7 | E42: 1052.9 | F42: =D42+E42 -> 3638.6 | G42: 998.5 | H42: 0 | I42: =G42+H42 -> 998.5 | J42: =D42-G42 -> 1587.2 | K42: =E42-H42 -> 1052.9 | L42: =J42*0.1 -> 158.72 | M42: =K42*0.1 -> 105.29 | N42: =F42-I42 -> 2640.1 | O42: =N42*0.1 -> 264.01 | Q42: =TEXT(D42,"#.###,00") -> 2.585,70 | R42: =TEXT(E42,"#.###,00") -> 1.052,90 | S42: =TEXT(F42,"#.###,00") -> 3.638,60 | T42: =TEXT(G42,"#.###,00") -> 998,50 | U42: =TEXT(H42,"#.###,00") -> ,00 | V42: =TEXT(I42,"#.###,00") -> 998,50 | W42: =TEXT(J42,"#.###,00") -> 1.587,20 | X42: =TEXT(K42,"#.###,00") -> 1.052,90 | ... AB42: =TEXT(O42,"#.###,00") -> 264,01
...

Sheet Excel4
A1: SIRA | B1: BELEDİYE | C1: İL | D1: İLÇE İL | E1: ÜRETİM.BİNA | F1: ÜRT.MUHT. | G1: İPTAL.BİNA | H1: İPTAL.MUHT. | I1: NET PRİM | J1: YSV | K1: kontrol | L1: ilçe il BİRLEŞTİR | M1: X
A2: 1 | B2: ADANA BÜYÜKŞEHİR | C2: ADANA | D2: =L2 -> ADANA BÜYÜKŞEHİR / ADANA | E2: 174202.41 | F2: 154813.22 | G2: 10663.7 | H2: 13590.9 | I2: 304761.03 | J2: 30476.1 | K2: =VLOOKUP(D2,Excel6!A:H,8,0) -> 30476.1 | L2: =CONCATENATE(B2& " / " &C2) -> ADANA BÜYÜKŞEHİR / ADANA | M2: =J2-K2 -> 0
A3: 2 | B3: MERKEZ | C3: ADIYAMAN | D3: =L3 -> MERKEZ / ADIYAMAN | E3: 12248.3 | F3: 15964.6 | G3: 802.4 | H3: 1371.1 | I3: 26039.4 | J3: 2603.94 | K3: =VLOOKUP(D3,Excel6!A:H,8,0) -> 2603.94 | L3: =CONCATENATE(B3& " / " &C3) -> MERKEZ / ADIYAMAN | M3: =J3-K3 -> 0
A4: 3 | B4: KAHTA | C4: ADIYAMAN | D4: =L4 -> KAHTA / ADIYAMAN | E4: 1905.1 | F4: 3151.8 | G4: 0 | H4: 0 | I4: 5056.9 | J4: 505.69 | K4: =VLOOKUP(D4,Excel6!A:H,8,0) -> 505.69 | L4: =CONCATENATE(B4& " / " &C4) -> KAHTA / ADIYAMAN | M4: =J4-K4 -> 0
A5: 4 | B5: BESNİ | C5: ADIYAMAN | D5: =L5 -> BESNİ / ADIYAMAN | E5: 261.1 | F5: 449.6 | G5: 0 | H5: 0 | I5: 710.7 | J5: 71.07 | K5: =VLOOKUP(D5,Excel6!A:H,8,0) -> 71.07 | L5: =CONCATENATE(B5& " / " &C5) -> BESNİ / ADIYAMAN | M5: =J5-K5 -> 0
A6: 5 | B6: ÇELİKHAN | C6: ADIYAMAN | D6: =L6 -> ÇELİKHAN / ADIYAMAN | E6: 307.4 | F6: 118 | G6: 0 | H6: 0 | I6: 425.4 | J6: 42.54 | K6: =VLOOKUP(D6,Excel6!A:H,8,0) -> 42.54 | L6: =CONCATENATE(B6& " / " &C6) -> ÇELİKHAN / ADIYAMAN | M6: =J6-K6 -> 0
A7: 6 | B7: GÖLBAŞI | C7: ADIYAMAN | D7: =L7 -> GÖLBAŞI / ADIYAMAN | E7: 88.6 | F7: 134.3 | G7: 0 | H7: 0 | I7: 222.9 | J7: 22.29 | K7: =VLOOKUP(D7,Excel6!A:H,8,0) -> 22.29 | L7: =CONCATENATE(B7& " / " &C7) -> GÖLBAŞI / ADIYAMAN | M7: =J7-K7 -> 0
A8: 7 | B8: MERKEZ | C8: AFYONKARAHİSAR | D8: =L8 -> MERKEZ / AFYONKARAHİSAR | E8: 30076.5 | F8: 55308.7 | G8: 344 | H8: 282.9 | I8: 84758.3 | J8: 8475.83 | K8: =VLOOKUP(D8,Excel6!A:H,8,0) -> 8475.83 | L8: =CONCATENATE(B8& " / " &C8) -> MERKEZ / AFYONKARAHİSAR | M8: =J8-K8 -> 0
A9: 8 | B9: ÇAY | C9: AFYONKARAHİSAR | D9: =L9 -> ÇAY / AFYONKARAHİSAR | E9: 51763.5 | G9: 0 | I9: 51763.5 | J9: 5176.35 | K9: =VLOOKUP(D9,Excel6!A:H,8,0) -> 5176.35 | L9: =CONCATENATE(B9& " / " &C9) -> ÇAY / AFYONKARAHİSAR | M9: =J9-K9 -> 0
A10: 9 | B10: ŞUHUT | C10: AFYONKARAHİSAR | D10: =L10 -> ŞUHUT / AFYONKARAHİSAR | E10: 4257 | F10: 1005.5 | G10: 0 | H10: 0 | I10: 5262.5 | J10: 526.25 | K10: =VLOOKUP(D10,Excel6!A:H,8,0) -> 526.25 | L10: =CONCATENATE(B10& " / " &C10) -> ŞUHUT / AFYONKARAHİSAR | M10: =J10-K10 -> 0
A11: 10 | B11: İSCEHİSAR | C11: AFYONKARAHİSAR | D11: =L11 -> İSCEHİSAR / AFYONKARAHİSAR | E11: 2151.9 | F11: 199.1 | G11: 0 | H11: 0 | I11: 2351 | J11: 235.1 | K11: =VLOOKUP(D11,Excel6!A:H,8,0) -> 235.1 | L11: =CONCATENATE(B11& " / " &C11) -> İSCEHİSAR / AFYONKARAHİSAR | M11: =J11-K11 -> 0
A12: 11 | B12: DİNAR | C12: AFYONKARAHİSAR | D12: =L12 -> DİNAR / AFYONKARAHİSAR | E12: 890.4 | F12: 1468.4 | G12: 21.7 | H12: 12.1 | I12: 2325 | J12: 232.5 | K12: =VLOOKUP(D12,Excel6!A:H,8,0) -> 232.5 | L12: =CONCATENATE(B12& " / " &C12) -> DİNAR / AFYONKARAHİSAR | M12: =J12-K12 -> 0
A13: 12 | B13: DAZKIRI | C13: AFYONKARAHİSAR | D13: =L13 -> DAZKIRI / AFYONKARAHİSAR | E13: 0.2 | F13: 2049.3 | G13: 0 | H13: 0 | I13: 2049.5 | J13: 204.95 | K13: =VLOOKUP(D13,Excel6!A:H,8,0) -> 204.95 | L13: =CONCATENATE(B13& " / " &C13) -> DAZKIRI / AFYONKARAHİSAR | M13: =J13-K13 -> 0
A14: 13 | B14: İHSANİYE | C14: AFYONKARAHİSAR | D14: =L14 -> İHSANİYE / AFYONKARAHİSAR | E14: 0.1 | F14: 1335.8 | G14: 0 | H14: 0 | I14: 1335.9 | J14: 133.59 | K14: =VLOOKUP(D14,Excel6!A:H,8,0) -> 133.59 | L14: =CONCATENATE(B14& " / " &C14) -> İHSANİYE / AFYONKARAHİSAR | M14: =J14-K14 -> 0
A15: 14 | B15: SULTANDAĞI | C15: AFYONKARAHİSAR | D15: =L15 -> SULTANDAĞI / AFYONKARAHİSAR | E15: 688.6 | F15: 478.1 | G15: 0 | H15: 0 | I15: 1166.7 | J15: 116.67 | K15: =VLOOKUP(D15,Excel6!A:H,8,0) -> 116.67 | L15: =CONCATENATE(B15& " / " &C15) -> SULTANDAĞI / AFYONKARAHİSAR | M15: =J15-K15 -> 0
A16: 15 | B16: EMİRDAĞ | C16: AFYONKARAHİSAR | D16: =L16 -> EMİRDAĞ / AFYONKARAHİSAR | E16: 909.3 | F16: 256.5 | G16: 23.3 | H16: 0 | I16: 1142.5 | J16: 114.25 | K16: =VLOOKUP(D16,Excel6!A:H,8,0) -> 114.25 | L16: =CONCATENATE(B16& " / " &C16) -> EMİRDAĞ / AFYONKARAHİSAR | M16: =J16-K16 -> 0
A17: 16 | B17: SİNANPAŞA | C17: AFYONKARAHİSAR | D17: =L17 -> SİNANPAŞA / AFYONKARAHİSAR | E17: 188.1 | F17: 793.7 | G17: 0 | H17: 0 | I17: 981.8 | J17: 98.18 | K17: =VLOOKUP(D17,Excel6!A:H,8,0) -> 98.18 | L17: =CONCATENATE(B17& " / " &C17) -> SİNANPAŞA / AFYONKARAHİSAR | M17: =J17-K17 -> 0
A18: 17 | B18: SANDIKLI | C18: AFYONKARAHİSAR | D18: =L18 -> SANDIKLI / AFYONKARAHİSAR | E18: 207.2 | F18: 569.4 | G18: 0 | H18: 0 | I18: 776.6 | J18: 77.66 | K18: =VLOOKUP(D18,Excel6!A:H,8,0) -> 77.66 | L18: =CONCATENATE(B18& " / " &C18) -> SANDIKLI / AFYONKARAHİSAR | M18: =J18-K18 -> 0
A19: 18 | B19: BOLVADİN | C19: AFYONKARAHİSAR | D19: =L19 -> BOLVADİN / AFYONKARAHİSAR | E19: 258.4 | F19: 411 | G19: 0 | H19: 0 | I19: 669.4 | J19: 66.94 | K19: =VLOOKUP(D19,Excel6!A:H,8,0) -> 66.94 | L19: =CONCATENATE(B19& " / " &C19) -> BOLVADİN / AFYONKARAHİSAR | M19: =J19-K19 -> 0
A20: 19 | B20: SİNANPAŞA | C20: AFYONKARAHİSAR | D20: =L20 -> SİNANPAŞA / AFYONKARAHİSAR | E20: 299.8 | F20: 281.8 | G20: 0 | H20: 0 | I20: 581.6 | J20: 58.16 | K20: =VLOOKUP(D20,Excel6!A:H,8,0) -> 58.16 | L20: =CONCATENATE(B20& " / " &C20) -> SİNANPAŞA / AFYONKARAHİSAR | M20: =J20-K20 -> 0
A21: 20 | B21: HOCALAR | C21: AFYONKARAHİSAR | D21: =L21 -> HOCALAR / AFYONKARAHİSAR | E21: 246.6 | F21: 129.8 | G21: 4.2 | H21: 57.2 | I21: 315 | J21: 31.5 | K21: =VLOOKUP(D21,Excel6!A:H,8,0) -> 31.5 | L21: =CONCATENATE(B21& " / " &C21) -> HOCALAR / AFYONKARAHİSAR | M21: =J21-K21 -> 0
... A26: 25 | B26: SULTANHANI | C26: AKSARAY | D26: =L26 -> SULTANHANI / AKSARAY | E26: 15822.4 | F26: 10439.7 | G26: 7826.9 | H26: 6006.3 | I26: 12428.9 | J26: 1242.89 | K26: =VLOOKUP(D26,Excel6!A:H,8,0) -> 1242.89 | L26: =CONCATENATE(B26& " / " &C26) -> SULTANHANI / AKSARAY | M26: =J26-K26 -> 0
A27: 26 | B27: AĞAÇÖREN | C27: AKSARAY | D27: =L27 -> AĞAÇÖREN / AKSARAY | F27: 4362.3 | H27: 0 | I27: 4362.3 | J27: 436.23 | K27: =VLOOKUP(D27,Excel6!A:H,8,0) -> 436.23 | L27: =CONCATENATE(B27& " / " &C27) -> AĞAÇÖREN / AKSARAY | M27: =J27-K27 -> 0
A28: 27 | B28: ESKİL | C28: AKSARAY | D28: =L28 -> ESKİL / AKSARAY | E28: 551 | F28: 2947.3 | G28: 110.2 | H28: 587.1 | I28: 2801 | J28: 280.1 | K28: =VLOOKUP(D28,Excel6!A:H,8,0) -> 280.1 | L28: =CONCATENATE(B28& " / " &C28) -> ESKİL / AKSARAY | M28: =J28-K28 -> 0
A29: 28 | B29: ORTAKÖY | C29: AKSARAY | D29: =L29 -> ORTAKÖY / AKSARAY | E29: 310.4 | F29: 401.2 | G29: 0 | H29: 0 | I29: 711.6 | J29: 71.16 | K29: =VLOOKUP(D29,Excel6!A:H,8,0) -> 71.16 | L29: =CONCATENATE(B29& " / " &C29) -> ORTAKÖY / AKSARAY | M29: =J29-K29 -> 0
A30: 29 | B30: GÜZELYURT | C30: AKSARAY | D30: =L30 -> GÜZELYURT / AKSARAY | E30: 85.8 | F30: 51.9 | G30: 0.1 | H30: 0 | I30: 137.6 | J30: 13.76 | K30: =VLOOKUP(D30,Excel6!A:H,8,0) -> 13.76 | L30: =CONCATENATE(B30& " / " &C30) -> GÜZELYURT / AKSARAY | M30: =J30-K30 -> 0
A31: 30 | B31: MERKEZ | C31: AMASYA | D31: =L31 -> MERKEZ / AMASYA | E31: 18996.4 | F31: 45496 | G31: 173.7 | H31: 602.3 | I31: 63716.4 | J31: 6371.64 | K31: =VLOOKUP(D31,Excel6!A:H,8,0) -> 6371.64 | L31: =CONCATENATE(B31& " / " &C31) -> MERKEZ / AMASYA | M31: =J31-K31 -> 0
A32: 31 | B32: MERZİFON | C32: AMASYA | D32: =L32 -> MERZİFON / AMASYA | E32: 5248.4 | F32: 2442.3 | G32: 45 | H32: 402.8 | I32: 7242.9 | J32: 724.29 | K32: =VLOOKUP(D32,Excel6!A:H,8,0) -> 724.29 | L32: =CONCATENATE(B32& " / " &C32) -> MERZİFON / AMASYA | M32: =J32-K32 -> 0
A33: 32 | B33: GÜMÜŞHACIKÖY | C33: AMASYA | D33: =L33 -> GÜMÜŞHACIKÖY / AMASYA | E33: 377.1 | F33: 313.3 | G33: 0 | H33: 0 | I33: 690.4 | J33: 69.04 | K33: =VLOOKUP(D33,Excel6!A:H,8,0) -> 69.04 | L33: =CONCATENATE(B33& " / " &C33) -> GÜMÜŞHACIKÖY / AMASYA | M33: =J33-K33 -> 0
A34: 33 | B34: GÖYNÜCEK | C34: AMASYA | D34: =L34 -> GÖYNÜCEK / AMASYA | E34: 5.4 | F34: 103.3 | G34: 0 | H34: 0 | I34: 108.7 | J34: 10.87 | K34: =VLOOKUP(D34,Excel6!A:H,8,0) -> 10.87 | L34: =CONCATENATE(B34& " / " &C34) -> GÖYNÜCEK / AMASYA | M34: =J34-K34 -> 0
A35: 34 | B35: TAŞOVA | C35: AMASYA | D35: =L35 -> TAŞOVA / AMASYA | E35: 5.4 | F35: 103.3 | G35: 0 | H35: 0 | I35: 108.7 | J35: 10.87 | K35: =VLOOKUP(D35,Excel6!A:H,8,0) -> 10.87 | L35: =CONCATENATE(B35& " / " &C35) -> TAŞOVA / AMASYA | M35: =J35-K35 -> 0
A36: 35 | B36: SULUOVA | C36: AMASYA | D36: =L36 -> SULUOVA / AMASYA | E36: 207 | G36: 126.4 | I36: 80.6 | J36: 8.06 | K36: =VLOOKUP(D36,Excel6!A:H,8,0) -> 8.06 | L36: =CONCATENATE(B36& " / " &C36) -> SULUOVA / AMASYA | M36: =J36-K36 -> 0
A37: 36 | B37: ANKARA BÜYÜKŞEHİR | C37: ANKARA | D37: =L37 -> ANKARA BÜYÜKŞEHİR / ANKARA | E37: 1011237.3 | F37: 1497153.8 | G37: 51577.41 | H37: 107930.46 | I37: 2348883.2 | J37: 234888.37 | K37: =VLOOKUP(D37,Excel6!A:H,8,0) -> 234888.37 | L37: =CONCATENATE(B37& " / " &C37) -> ANKARA BÜYÜKŞEHİR / ANKARA | M37: =J37-K37 -> 0
A38: 37 | B38: ANTALYA BÜYÜKŞEHİR | C38: ANTALYA | D38: =L38 -> ANTALYA BÜYÜKŞEHİR / ANTALYA | E38: 656158.68 | F38: 1043094.9 | G38: 66212.22 | H38: 73315.48 | I38: 1559725.9 | J38: 155972.61 | K38: =VLOOKUP(D38,Excel6!A:H,8,0) -> 155972.61 | L38: =CONCATENATE(B38& " / " &C38) -> ANTALYA BÜYÜKŞEHİR / ANTALYA | M38: =J38-K38 -> 0
A39: 38 | B39: MERKEZ | C39: ARDAHAN | D39: =L39 -> MERKEZ / ARDAHAN | E39: 4355 | F39: 2429.3 | G39: 1738.6 | H39: 28.3 | I39: 5017.4 | J39: 501.74 | K39: =VLOOKUP(D39,Excel6!A:H,8,0) -> 501.74 | L39: =CONCATENATE(B39& " / " &C39) -> MERKEZ / ARDAHAN | M39: =J39-K39 -> 0
A40: 39 | B40: GÖLE | C40: ARDAHAN | D40: =L40 -> GÖLE / ARDAHAN | E40: 1702.7 | F40: 502.7 | G40: 0 | H40: 0 | I40: 2205.4 | J40: 220.54 | K40: =VLOOKUP(D40,Excel6!A:H,8,0) -> 220.54 | L40: =CONCATENATE(B40& " / " &C40) -> GÖLE / ARDAHAN | M40: =J40-K40 -> 0
A41: 40 | B41: HANAK | C41: ARDAHAN | D41: =L41 -> HANAK / ARDAHAN | E41: 455.8 | F41: 45.8 | G41: 0 | H41: 0 | I41: 501.6 | J41: 50.16 | K41: =VLOOKUP(D41,Excel6!A:H,8,0) -> 50.16 | L41: =CONCATENATE(B41& " / " &C41) -> HANAK / ARDAHAN | M41: =J41-K41 -> 0
A42: 41 | B42: POSOF | C42: ARDAHAN | D42: =L42 -> POSOF / ARDAHAN | E42: 4.6 | F42: 478.5 | G42: 0 | H42: 0 | I42: 483.1 | J42: 48.31 | K42: =VLOOKUP(D42,Excel6!A:H,8,0) -> 48.31 | L42: =CONCATENATE(B42& " / " &C42) -> POSOF / ARDAHAN | M42: =J42-K42 -> 0
A43: 42 | B43: DAMAL | C43: ARDAHAN | D43: =L43 -> DAMAL / ARDAHAN | E43: 288.7 | F43: 186.4 | G43: 0 | H43: 0 | I43: 475.1 | J43: 47.51 | K43: =VLOOKUP(D43,Excel6!A:H,8,0) -> 47.51 | L43: =CONCATENATE(B43& " / " &C43) -> DAMAL / ARDAHAN | M43: =J43-K43 -> 0
A44: 43 | B44: HOPA | C44: ARTVİN | D44: =L44 -> HOPA / ARTVİN | E44: 2585.7 | F44: 1052.9 | G44: 998.5 | H44: 0 | I44: 2640.1 | J44: 264.01 | K44: =VLOOKUP(D44,Excel6!A:H,8,0) -> 264.01 | L44: =CONCATENATE(B44& " / " &C44) -> HOPA / ARTVİN | M44: =J44-K44 -> 0
...

Sheet Excel3
A1: BELEDIYE | B1: Il | C1: İlçe/İl | D1: ÜRETİM.BİNA | E1: ÜRT.MUHT. | F1: İPTAL.BİNA | G1: İPTAL.MUHT. | H1: NET PRİM | I1: YSV | J1: xx
A2: ADANA BÜYÜKŞEHİR | B2: ADANA | C2: ADANA BÜYÜKŞEHİR/ADANA | D2: 174202.41 | E2: 154813.22 | F2: 10663.7 | G2: 13590.9 | H2: 304761.03 | I2: 30476.1 | M2: =D2+E2-F2-G2 -> 304761.03 | N2: =H2-M2 -> 0 | O2: =M2*0.1 -> 30476.103 | P2: =I2-O2 -> -0.003
A3: MERKEZ | B3: ADIYAMAN | C3: MERKEZ/ADIYAMAN | D3: 12248.3 | E3: 15964.6 | F3: 802.4 | G3: 1371.1 | H3: 26039.4 | I3: 2603.94 | M3: =D3+E3-F3-G3 -> 26039.4 | N3: =H3-M3 -> 0 | O3: =M3*0.1 -> 2603.94 | P3: =I3-O3 -> 0
A4: KAHTA | B4: ADIYAMAN | C4: KAHTA/ADIYAMAN | D4: 1905.1 | E4: 3151.8 | F4: 0 | G4: 0 | H4: 5056.9 | I4: 505.69 | M4: =D4+E4-F4-G4 -> 5056.9 | N4: =H4-M4 -> 0 | O4: =M4*0.1 -> 505.69 | P4: =I4-O4 -> 0
A5: BESNİ | B5: ADIYAMAN | C5: BESNİ/ADIYAMAN | D5: 261.1 | E5: 449.6 | F5: 0 | G5: 0 | H5: 710.7 | I5: 71.07 | M5: =D5+E5-F5-G5 -> 710.7 | N5: =H5-M5 -> 0 | O5: =M5*0.1 -> 71.07 | P5: =I5-O5 -> 0
A6: ÇELİKHAN | B6: ADIYAMAN | C6: ÇELİKHAN/ADIYAMAN | D6: 307.4 | E6: 118 | F6: 0 | G6: 0 | H6: 425.4 | I6: 42.54 | M6: =D6+E6-F6-G6 -> 425.4 | N6: =H6-M6 -> 0 | O6: =M6*0.1 -> 42.54 | P6: =I6-O6 -> 0
A7: GÖLBAŞI | B7: ADIYAMAN | C7: GÖLBAŞI/ADIYAMAN | D7: 88.6 | E7: 134.3 | F7: 0 | G7: 0 | H7: 222.9 | I7: 22.29 | M7: =D7+E7-F7-G7 -> 222.9 | N7: =H7-M7 -> 0 | O7: =M7*0.1 -> 22.29 | P7: =I7-O7 -> 0
A8: MERKEZ | B8: AFYONKARAHİSAR | C8: MERKEZ/AFYONKARAHİSAR | D8: 30076.5 | E8: 55308.7 | F8: 344 | G8: 282.9 | H8: 84758.3 | I8: 8475.83 | M8: =D8+E8-F8-G8 -> 84758.3 | N8: =H8-M8 -> 0 | O8: =M8*0.1 -> 8475.83 | P8: =I8-O8 -> 0
A9: ÇAY | B9: AFYONKARAHİSAR | C9: ÇAY/AFYONKARAHİSAR | D9: 51763.5 | F9: 0 | H9: 51763.5 | I9: 5176.35 | M9: =D9+E9-F9-G9 -> 51763.5 | N9: =H9-M9 -> 0 | O9: =M9*0.1 -> 5176.35 | P9: =I9-O9 -> 0
A10: ŞUHUT | B10: AFYONKARAHİSAR | C10: ŞUHUT/AFYONKARAHİSAR | D10: 4257 | E10: 1005.5 | F10: 0 | G10: 0 | H10: 5262.5 | I10: 526.25 | M10: =D10+E10-F10-G10 -> 5262.5 | N10: =H10-M10 -> 0 | O10: =M10*0.1 -> 526.25 | P10: =I10-O10 -> 0
A11: İSCEHİSAR | B11: AFYONKARAHİSAR | C11: İSCEHİSAR/AFYONKARAHİSAR | D11: 2151.9 | E11: 199.1 | F11: 0 | G11: 0 | H11: 2351 | I11: 235.1 | M11: =D11+E11-F11-G11 -> 2351 | N11: =H11-M11 -> 0 | O11: =M11*0.1 -> 235.1 | P11: =I11-O11 -> 0
A12: DİNAR | B12: AFYONKARAHİSAR | C12: DİNAR/AFYONKARAHİSAR | D12: 890.4 | E12: 1468.4 | F12: 21.7 | G12: 12.1 | H12: 2325 | I12: 232.5 | M12: =D12+E12-F12-G12 -> 2325 | N12: =H12-M12 -> 0 | O12: =M12*0.1 -> 232.5 | P12: =I12-O12 -> 0
A13: DAZKIRI | B13: AFYONKARAHİSAR | C13: DAZKIRI/AFYONKARAHİSAR | D13: 0.2 | E13: 2049.3 | F13: 0 | G13: 0 | H13: 2049.5 | I13: 204.95 | M13: =D13+E13-F13-G13 -> 2049.5 | N13: =H13-M13 -> 0 | O13: =M13*0.1 -> 204.95 | P13: =I13-O13 -> 0
A14: İHSANİYE | B14: AFYONKARAHİSAR | C14: İHSANİYE/AFYONKARAHİSAR | D14: 0.1 | E14: 1335.8 | F14: 0 | G14: 0 | H14: 1335.9 | I14: 133.59 | M14: =D14+E14-F14-G14 -> 1335.9 | N14: =H14-M14 -> 0 | O14: =M14*0.1 -> 133.59 | P14: =I14-O14 -> 0
A15: SULTANDAĞI | B15: AFYONKARAHİSAR | C15: SULTANDAĞI/AFYONKARAHİSAR | D15: 688.6 | E15: 478.1 | F15: 0 | G15: 0 | H15: 1166.7 | I15: 116.67 | M15: =D15+E15-F15-G15 -> 1166.7 | N15: =H15-M15 -> 0 | O15: =M15*0.1 -> 116.67 | P15: =I15-O15 -> 0
A16: EMİRDAĞ | B16: AFYONKARAHİSAR | C16: EMİRDAĞ/AFYONKARAHİSAR | D16: 909.3 | E16: 256.5 | F16: 23.3 | G16: 0 | H16: 1142.5 | I16: 114.25 | M16: =D16+E16-F16-G16 -> 1142.5 | N16: =H16-M16 -> 0 | O16: =M16*0.1 -> 114.25 | P16: =I16-O16 -> 0
A17: SİNANPAŞA | B17: AFYONKARAHİSAR | C17: SİNANPAŞA /AFYONKARAHİSAR | D17: 188.1 | E17: 793.7 | F17: 0 | G17: 0 | H17: 981.8 | I17: 98.18 | M17: =D17+E17-F17-G17 -> 981.8 | N17: =H17-M17 -> 0 | O17: =M17*0.1 -> 98.18 | P17: =I17-O17 -> 0
